Workbook

Sheet District ADAEnrollment
A1: nixo | H1: 2024-2025 Sheldon ISD ADA Dashboard
A2: Estimated $ Missed Annually | H2: =CE!H3 -> 127930.15 | J2: =GE!H3 -> 165234.25 | L2: =ME!H3 -> 170567.29 | N2: =SAMPLE!H3 -> 149891.18 | P2: ='Sheldon Elementary'!E3 -> 158482.73 | R2: =SLE!H3 -> 218997.97 | T2: =CECA!H3 -> 219811 | V2: =SECA!H3 -> 234562.56 | X2: =KHS!H3 -> 863403.92 | Z2: ='9TH CAMP'!H3 -> 190510.48 | AB2: =ECHS!H3 -> 85247.476 | AD2: =KMS!H3 -> 318273.85 | AF2: =NMS!H3 -> 306724.01 | AH2: =SUM(H2:AG2) -> 3209636.8
H3: CE | J3: GE | L3: ME | N3: RE | P3: SE | R3: SLE | T3: CECA | V3: SECA | X3: KHS | Z3: 9TH GR CAMPUS | AB3: ECHS | AD3: KMS | AF3: NMS | AH3: Highpnt | AI3: KASE
H4: ADA | I4: Enrollment | J4: ADA | K4: Enrollment | L4: ADA | M4: Enrollment | N4: ADA | O4: Enrollment | P4: ADA | Q4: Enrollment | R4: ADA | S4: Enrollment | T4: ADA | U4: Enrollment | V4: ADA | W4: Enrollment | X4: ADA | Y4: Enrollment | Z4: ADA | AA4: Enrollment | AB4: ADA | AC4: Enrollment | AD4: ADA | AE4: Enrollment | AF4: ADA | AG4: Enrollment | AH4: Enrollment | AI4: Enrollment | AK4: KASE Weekly Attendance
A5: ADA % BY CAMPUS | H5: =AVERAGE(H12:H163) -> 0.91180887 | J5: =AVERAGE(J12:J163) -> 0.92102705 | L5: =AVERAGE(L12:L163) -> 0.92915246 | N5: =AVERAGE(N12:N163) -> 0.9335773 | P5: =AVERAGE(P12:P163) -> 0.93017377 | R5: =AVERAGE(R12:R163) -> 0.93403361 | T5: =AVERAGE(T12:T163) -> 0.90461639 | V5: =AVERAGE(V12:V163) -> 0.89872131 | X5: =AVERAGE(X12:X163) -> 0.90274918 | Z5: =AVERAGE(Z12:Z163) -> 0.91959344 | AB5: =AVERAGE(AB12:AB163) -> 0.91640079 | AD5: =AVERAGE(AD12:AD163) -> 0.93513115 | AF5: =AVERAGE(AF12:AF163) -> 0.91813525 | AH5: =AVERAGE(H5:AG5) -> 0.91962466
F6: EcoDis
H7: >>Click Here To View Your Students With Less Than 95% ADA<<
A8: # OF DAYS LESS THAN 95% ADA | H8: =COUNTIF(H12:H178,"<94%") -> 46 | J8: =COUNTIF(J12:J178,"<94%") -> 50 | L8: =COUNTIF(L12:L178,"<94%") -> 52 | N8: =COUNTIF(N12:N178,"<94%") -> 36 | P8: =COUNTIF(P12:P178,"<94%") -> 46 | R8: =COUNTIF(R12:R178,"<94%") -> 45 | T8: =COUNTIF(T12:T178,"<94%") -> 103 | V8: =COUNTIF(V12:V178,"<94%") -> 112 | X8: =COUNTIF(X12:X178,"<94%") -> 88 | Z8: =COUNTIF(Z12:Z178,"<94%") -> 75 | AB8: =COUNTIF(AB12:AB178,"<94%") -> 26 | AD8: =COUNTIF(AD12:AD178,"<94%") -> 26 | AF8: =COUNTIF(AF12:AF178,"<94%") -> 48
A9: # OF DAYS LESS THAN 90% ADA | H9: =COUNTIF(H12:H179,"<90%") -> 19 | J9: =COUNTIF(J12:J179,"<90%") -> 22 | L9: =COUNTIF(L12:L179,"<90%") -> 22 | N9: =COUNTIF(N12:N179,"<90%") -> 18 | P9: =COUNTIF(P12:P179,"<90%") -> 19 | R9: =COUNTIF(R12:R179,"<90%") -> 15 | T9: =COUNTIF(T12:T179,"<90%") -> 29 | V9: =COUNTIF(V12:V179,"<90%") -> 43 | X9: =COUNTIF(X12:X179,"<90%") -> 21 | Z9: =COUNTIF(Z12:Z179,"<90%") -> 22 | AB9: =COUNTIF(AB12:AB179,"<90%") -> 18 | AD9: =COUNTIF(AD12:AD179,"<90%") -> 16 | AF9: =COUNTIF(AF12:AF179,"<90%") -> 22
A10: TOTAL OPERATIONAL MINUTES | H10: =B220 -> 76500
A11: MINS | C11: DAYS | D11: DATE | E11: DAY | G11: ENR
B12: 450 | C12: Day 1 | D12: 45516 | E12: Monday | G12: =I12+K12+M12+O12+Q12+S12+U12+W12+Y12+AA12+AC12+AE12+AG12+AI12+AH12 -> 9729 | H12: =CE!C7 -> 1 | I12: =CE!G7 -> 486 | J12: =GE!C7 -> 1 | K12: =GE!G7 -> 549 | L12: =ME!C7 -> 1 | M12: =ME!G7 -> 560 | N12: =SAMPLE!C7 -> 1 | O12: =SAMPLE!G7 -> 536 | P12: ='Sheldon Elementary'!C7 -> 1 | Q12: ='Sheldon Elementary'!D7 -> 558 | R12: =SLE!C7 -> 1 | S12: =SLE!G7 -> 585 | T12: =CECA!C7 -> 1 | U12: =CECA!G7 -> 472 | V12: =SECA!C7 -> 1 | W12: =SECA!G7 -> 464 | X12: =KHS!C7 -> 1 | Y12: =KHS!G7 -> 2360 | Z12: ='9TH CAMP'!C7 -> 1 | AA12: ='9TH CAMP'!G7 -> 524 | AB12: =ECHS!C7 -> 1 | AC12: =ECHS!G7 -> 438 | AD12: =KMS!C7 -> 1 | AE12: =KMS!G7 -> 1213 | AF12: =NMS!C7 -> 1 | AG12: =NMS!G7 -> 924 | AH12: =Highpoint!C6 -> 0 | AI12: =KASE!D4 -> 60 | AK12: =AVERAGE(H12,J12,L12,N12,P12,R12,T12,V12,X12,Z12,AB12,AD12,AF12) -> 1
B13: =B12+450 -> 900 | C13: Day 2 | D13: 45517 | E13: Tuesday | G13: =I13+K13+M13+O13+Q13+S13+U13+W13+Y13+AA13+AC13+AE13+AG13+AI13+AH13 -> 10084 | H13: =CE!C8 -> 0.998 | I13: =CE!G8 -> 501 | J13: =GE!C8 -> 0.9965 | K13: =GE!G8 -> 571 | L13: =ME!C8 -> 0.9948 | M13: =ME!G8 -> 581 | N13: =SAMPLE!C8 -> 0.9911 | O13: =SAMPLE!G8 -> 559 | P13: ='Sheldon Elementary'!C8 -> 0.9878 | Q13: ='Sheldon Elementary'!D8 -> 572 | R13: =SLE!C8 -> 0.9813 | S13: =SLE!G8 -> 591 | T13: =CECA!C8 -> 0.9873 | U13: =CECA!G8 -> 485 | V13: =SECA!C8 -> 0.9886 | W13: =SECA!G8 -> 487 | X13: =KHS!C8 -> 0.9796 | Y13: =KHS!G8 -> 2447 | Z13: ='9TH CAMP'!C8 -> 0.976 | AA13: ='9TH CAMP'!G8 -> 541 | AB13: =ECHS!C8 -> 0.9911 | AC13: =ECHS!G8 -> 449 | AD13: =KMS!C8 -> 0.9851 | AE13: =KMS!G8 -> 1271 | AF13: =NMS!C8 -> 0.9668 | AG13: =NMS!G8 -> 964 | AH13: =Highpoint!C7 -> 0 | AI13: =KASE!D5 -> 65 | AK13: =AVERAGE(H13,J13,L13,N13,P13,R13,T13,V13,X13,Z13,AB13,AD13,AF13) -> 0.98646154
B14: =B13+450 -> 1350 | C14: Day 3 | D14: 45518 | E14: Wednesday | G14: =I14+K14+M14+O14+Q14+S14+U14+W14+Y14+AA14+AC14+AE14+AG14+AI14+AH14 -> 10300 | H14: =CE!C9 -> 0.9942 | I14: =CE!G9 -> 514 | J14: =GE!C9 -> 0.9826 | K14: =GE!G9 -> 575 | L14: =ME!C9 -> 0.9915 | M14: =ME!G9 -> 589 | N14: =SAMPLE!C9 -> 0.9772 | O14: =SAMPLE!G9 -> 570 | P14: ='Sheldon Elementary'!C9 -> 0.9757 | Q14: ='Sheldon Elementary'!D9 -> 577 | R14: =SLE!C9 -> 0.9832 | S14: =SLE!G9 -> 599 | T14: =CECA!C9 -> 0.9888 | U14: =CECA!G9 -> 493 | V14: =SECA!C9 -> 0.9809 | W14: =SECA!G9 -> 495 | X14: =KHS!C9 -> 0.9726 | Y14: =KHS!G9 -> 2520 | Z14: ='9TH CAMP'!C9 -> 0.9877 | AA14: ='9TH CAMP'!G9 -> 571 | AB14: =ECHS!C9 -> 0.9734 | AC14: =ECHS!G9 -> 451 | AD14: =KMS!C9 -> 0.983 | AE14: =KMS!G9 -> 1293 | AF14: =NMS!C9 -> 0.9695 | AG14: =NMS!G9 -> 986 | AH14: =Highpoint!C8 -> 0 | AI14: =KASE!D6 -> 67 | AK14: =AVERAGE(H14,J14,L14,N14,P14,R14,T14,V14,X14,Z14,AB14,AD14,AF14) -> 0.98156154
B15: =B14+450 -> 1800 | C15: Day 4 | D15: 45519 | E15: Thursday | G15: =I15+K15+M15+O15+Q15+S15+U15+W15+Y15+AA15+AC15+AE15+AG15+AI15+AH15 -> 9874 | H15: =CE!C10 -> 0 | I15: =CE!G10 -> 0 | J15: =GE!C10 -> 0.9861 | K15: =GE!G10 -> 576 | L15: =ME!C10 -> 0.9815 | M15: =ME!G10 -> 594 | N15: =SAMPLE!C10 -> 0.9774 | O15: =SAMPLE!G10 -> 576 | P15: ='Sheldon Elementary'!C10 -> 0.9743 | Q15: ='Sheldon Elementary'!D10 -> 583 | R15: =SLE!C10 -> 0.985 | S15: =SLE!G10 -> 604 | T15: =CECA!C10 -> 0.9667 | U15: =CECA!G10 -> 501 | V15: =SECA!C10 -> 0.946 | W15: =SECA!G10 -> 503 | X15: =KHS!C10 -> 0.9676 | Y15: =KHS!G10 -> 2529 | Z15: ='9TH CAMP'!C10 -> 0.9726 | AA15: ='9TH CAMP'!G10 -> 583 | AB15: =ECHS!C10 -> 0.9867 | AC15: =ECHS!G10 -> 452 | AD15: =KMS!C10 -> 0.9769 | AE15: =KMS!G10 -> 1301 | AF15: =NMS!C10 -> 0.9731 | AG15: =NMS!G10 -> 1002 | AH15: =Highpoint!C9 -> 0 | AI15: =KASE!D7 -> 70 | AK15: =AVERAGE(H15,J15,L15,N15,P15,R15,T15,V15,X15,Z15,AB15,AD15,AF15) -> 0.89953077
B16: =B15+450 -> 2250 | C16: Day 5 | D16: 45520 | E16: Friday | G16: =I16+K16+M16+O16+Q16+S16+U16+W16+Y16+AA16+AC16+AE16+AG16+AI16+AH16 -> 10438 | H16: =CE!C11 -> 0.9711 | I16: =CE!G11 -> 519 | J16: =GE!C11 -> 0.9587 | K16: =GE!G11 -> 581 | L16: =ME!C11 -> 0.9613 | M16: =ME!G11 -> 594 | N16: =SAMPLE!C11 -> 0.9652 | O16: =SAMPLE!G11 -> 577 | P16: ='Sheldon Elementary'!C11 -> 0.976 | Q16: ='Sheldon Elementary'!D11 -> 583 | R16: =SLE!C11 -> 0.9785 | S16: =SLE!G11 -> 608 | T16: =CECA!C11 -> 0.9407 | U16: =CECA!G11 -> 503 | V16: =SECA!C11 -> 0.9242 | W16: =SECA!G11 -> 515 | X16: =KHS!C11 -> 0.9555 | Y16: =KHS!G11 -> 2538 | Z16: ='9TH CAMP'!C11 -> 0.9503 | AA16: ='9TH CAMP'!G11 -> 583 | AB16: =ECHS!C11 -> 0.958 | AC16: =ECHS!G11 -> 452 | AD16: =KMS!C11 -> 0.9565 | AE16: =KMS!G11 -> 1310 | AF16: =NMS!C11 -> 0.9542 | AG16: =NMS!G11 -> 1004 | AH16: =Highpoint!C10 -> 0 | AI16: =KASE!D8 -> 71 | AK16: =AVERAGE(H16,J16,L16,N16,P16,R16,T16,V16,X16,Z16,AB16,AD16,AF16) -> 0.95770769
B17: =B16+450 -> 2700 | C17: Day 6 | D17: 45523 | E17: Monday | G17: =I17+K17+M17+O17+Q17+S17+U17+W17+Y17+AA17+AC17+AE17+AG17+AI17+AH17 -> 10570 | H17: =CE!C12 -> 0.9771 | I17: =CE!G12 -> 524 | J17: =GE!C12 -> 0.9464 | K17: =GE!G12 -> 597 | L17: =ME!C12 -> 0.9473 | M17: =ME!G12 -> 607 | N17: =SAMPLE!C12 -> 0.962 | O17: =SAMPLE!G12 -> 579 | P17: ='Sheldon Elementary'!C12 -> 0.9591 | Q17: ='Sheldon Elementary'!D12 -> 587 | R17: =SLE!C12 -> 0.9446 | S17: =SLE!G12 -> 614 | T17: =CECA!C12 -> 0.9329 | U17: =CECA!G12 -> 509 | V17: =SECA!C12 -> 0.9063 | W17: =SECA!G12 -> 529 | X17: =KHS!C12 -> 0.9541 | Y17: =KHS!G12 -> 2570 | Z17: ='9TH CAMP'!C12 -> 0.9557 | AA17: ='9TH CAMP'!G12 -> 587 | AB17: =ECHS!C12 -> 0.9648 | AC17: =ECHS!G12 -> 454 | AD17: =KMS!C12 -> 0.9697 | AE17: =KMS!G12 -> 1322 | AF17: =NMS!C12 -> 0.9606 | AG17: =NMS!G12 -> 1015 | AH17: =Highpoint!C11 -> 0 | AI17: =KASE!D9 -> 76 | AK17: =AVERAGE(H17,J17,L17,N17,P17,R17,T17,V17,X17,Z17,AB17,AD17,AF17) -> 0.95235385
B18: =B17+450 -> 3150 | C18: Day 7 | D18: 45524 | E18: Tuesday | G18: =I18+K18+M18+O18+Q18+S18+U18+W18+Y18+AA18+AC18+AE18+AG18+AI18+AH18 -> 10625 | H18: =CE!C13 -> 0.9716 | I18: =CE!G13 -> 529 | J18: =GE!C13 -> 0.975 | K18: =GE!G13 -> 599 | L18: =ME!C13 -> 0.9362 | M18: =ME!G13 -> 611 | N18: =SAMPLE!C13 -> 0.9639 | O18: =SAMPLE!G13 -> 582 | P18: ='Sheldon Elementary'!C13 -> 0.9474 | Q18: ='Sheldon Elementary'!D13 -> 589 | R18: =SLE!C13 -> 0.9642 | S18: =SLE!G13 -> 615 | T18: =CECA!C13 -> 0.9359 | U18: =CECA!G13 -> 514 | V18: =SECA!C13 -> 0.9302 | W18: =SECA!G13 -> 535 | X18: =KHS!C13 -> 0.9593 | Y18: =KHS!G13 -> 2580 | Z18: ='9TH CAMP'!C13 -> 0.9525 | AA18: ='9TH CAMP'!G13 -> 589 | AB18: =ECHS!C13 -> 0.9648 | AC18: =ECHS!G13 -> 454 | AD18: =KMS!C13 -> 0.9676 | AE18: =KMS!G13 -> 1327 | AF18: =NMS!C13 -> 0.9619 | AG18: =NMS!G13 -> 1024 | AH18: =Highpoint!C12 -> 0 | AI18: =KASE!D10 -> 77 | AK18: =AVERAGE(H18,J18,L18,N18,P18,R18,T18,V18,X18,Z18,AB18,AD18,AF18) -> 0.95619231
B19: =B18+450 -> 3600 | C19: Day 8 | D19: 45525 | E19: Wednesday | G19: =I19+K19+M19+O19+Q19+S19+U19+W19+Y19+AA19+AC19+AE19+AG19+AI19+AH19 -> 10682 | H19: =CE!C14 -> 0.966 | I19: =CE!G14 -> 530 | J19: =GE!C14 -> 0.9635 | K19: =GE!G14 -> 603 | L19: =ME!C14 -> 0.9378 | M19: =ME!G14 -> 611 | N19: =SAMPLE!C14 -> 0.9692 | O19: =SAMPLE!G14 -> 584 | P19: ='Sheldon Elementary'!C14 -> 0.9492 | Q19: ='Sheldon Elementary'!D14 -> 591 | R19: =SLE!C14 -> 0.9756 | S19: =SLE!G14 -> 616 | T19: =CECA!C14 -> 0.9293 | U19: =CECA!G14 -> 519 | V19: =SECA!C14 -> 0.9352 | W19: =SECA!G14 -> 540 | X19: =KHS!C14 -> 0.9625 | Y19: =KHS!G14 -> 2587 | Z19: ='9TH CAMP'!C14 -> 0.9695 | AA19: ='9TH CAMP'!G14 -> 590 | AB19: =ECHS!C14 -> 0.9758 | AC19: =ECHS!G14 -> 455 | AD19: =KMS!C14 -> 0.9482 | AE19: =KMS!G14 -> 1332 | AF19: =NMS!C14 -> 0.964 | AG19: =NMS!G14 -> 1027 | AH19: =Highpoint!C13 -> 0 | AI19: =KASE!D11 -> 97 | AK19: =AVERAGE(H19,J19,L19,N19,P19,R19,T19,V19,X19,Z19,AB19,AD19,AF19) -> 0.95736923
B20: =B19+450 -> 4050 | C20: Day 9 | D20: 45526 | E20: Thursday | G20: =I20+K20+M20+O20+Q20+S20+U20+W20+Y20+AA20+AC20+AE20+AG20+AI20+AH20 -> 10712 | H20: =CE!C15 -> 0.9718 | I20: =CE!G15 -> 531 | J20: =GE!C15 -> 0.9635 | K20: =GE!G15 -> 603 | L20: =ME!C15 -> 0.9575 | M20: =ME!G15 -> 612 | N20: =SAMPLE!C15 -> 0.9727 | O20: =SAMPLE!G15 -> 586 | P20: ='Sheldon Elementary'!C15 -> 0.9713 | Q20: ='Sheldon Elementary'!D15 -> 592 | R20: =SLE!C15 -> 0.966 | S20: =SLE!G15 -> 618 | T20: =CECA!C15 -> 0.9401 | U20: =CECA!G15 -> 520 | V20: =SECA!C15 -> 0.9316 | W20: =SECA!G15 -> 544 | X20: =KHS!C15 -> 0.9526 | Y20: =KHS!G15 -> 2594 | Z20: ='9TH CAMP'!C15 -> 0.9511 | AA20: ='9TH CAMP'!G15 -> 593 | AB20: =ECHS!C15 -> 0.9781 | AC20: =ECHS!G15 -> 456 | AD20: =KMS!C15 -> 0.964 | AE20: =KMS!G15 -> 1335 | AF20: =NMS!C15 -> 0.9573 | AG20: =NMS!G15 -> 1031 | AH20: =Highpoint!C14 -> 0 | AI20: =KASE!D12 -> 97 | AK20: =AVERAGE(H20,J20,L20,N20,P20,R20,T20,V20,X20,Z20,AB20,AD20,AF20) -> 0.95981538
B21: =B20+450 -> 4500 | C21: Day 10 | D21: 45527 | E21: Friday | G21: =I21+K21+M21+O21+Q21+S21+U21+W21+Y21+AA21+AC21+AE21+AG21+AI21+AH21 -> 10724 | H21: =CE!C16 -> 0.9455 | I21: =CE!G16 -> 532 | J21: =GE!C16 -> 0.932 | K21: =GE!G16 -> 603 | L21: =ME!C16 -> 0.9331 | M21: =ME!G16 -> 613 | N21: =SAMPLE!C16 -> 0.9608 | O21: =SAMPLE!G16 -> 586 | P21: ='Sheldon Elementary'!C16 -> 0.9356 | Q21: ='Sheldon Elementary'!D16 -> 590 | R21: =SLE!C16 -> 0.966 | S21: =SLE!G16 -> 619 | T21: =CECA!C16 -> 0.92 | U21: =CECA!G16 -> 523 | V21: =SECA!C16 -> 0.9234 | W21: =SECA!G16 -> 546 | X21: =KHS!C16 -> 0.9415 | Y21: =KHS!G16 -> 2597 | Z21: ='9TH CAMP'!C16 -> 0.9222 | AA21: ='9TH CAMP'!G16 -> 591 | AB21: =ECHS!C16 -> 0.9606 | AC21: =ECHS!G16 -> 457 | AD21: =KMS!C16 -> 0.9454 | AE21: =KMS!G16 -> 1338 | AF21: =NMS!C16 -> 0.9264 | AG21: =NMS!G16 -> 1033 | AH21: =Highpoint!C15 -> 0 | AI21: =KASE!D13 -> 96 | AK21: =AVERAGE(H21,J21,L21,N21,P21,R21,T21,V21,X21,Z21,AB21,AD21,AF21) -> 0.93942308
B22: =B21+450 -> 4950 | C22: Day 11 | D22: 45530 | E22: Monday | G22: =I22+K22+M22+O22+Q22+S22+U22+W22+Y22+AA22+AC22+AE22+AG22+AI22+AH22 -> 10766 | H22: =CE!C17 -> 0.9346 | I22: =CE!G17 -> 535 | J22: =GE!C17 -> 0.9536 | K22: =GE!G17 -> 603 | L22: =ME!C17 -> 0.9383 | M22: =ME!G17 -> 616 | N22: =SAMPLE!C17 -> 0.9573 | O22: =SAMPLE!G17 -> 586 | P22: ='Sheldon Elementary'!C17 -> 0.939 | Q22: ='Sheldon Elementary'!D17 -> 590 | R22: =SLE!C17 -> 0.9515 | S22: =SLE!G17 -> 618 | T22: =CECA!C17 -> 0.9308 | U22: =CECA!G17 -> 532 | V22: =SECA!C17 -> 0.9096 | W22: =SECA!G17 -> 549 | X22: =KHS!C17 -> 0.9451 | Y22: =KHS!G17 -> 2606 | Z22: ='9TH CAMP'!C17 -> 0.9546 | AA22: ='9TH CAMP'!G17 -> 595 | AB22: =ECHS!C17 -> 0.9694 | AC22: =ECHS!G17 -> 457 | AD22: =KMS!C17 -> 0.9487 | AE22: =KMS!G17 -> 1345 | AF22: =NMS!C17 -> 0.9335 | AG22: =NMS!G17 -> 1037 | AH22: =Highpoint!C16 -> 0 | AI22: =KASE!D14 -> 97 | AK22: =AVERAGE(H22,J22,L22,N22,P22,R22,T22,V22,X22,Z22,AB22,AD22,AF22) -> 0.94353846
B23: =B22+450 -> 5400 | C23: Day 12 | D23: 45531 | E23: Tuesday | G23: =I23+K23+M23+O23+Q23+S23+U23+W23+Y23+AA23+AC23+AE23+AG23+AI23+AH23 -> 10790 | H23: =CE!C18 -> 0.9533 | I23: =CE!G18 -> 535 | J23: =GE!C18 -> 0.9586 | K23: =GE!G18 -> 604 | L23: =ME!C18 -> 0.9693 | M23: =ME!G18 -> 618 | N23: =SAMPLE!C18 -> 0.9728 | O23: =SAMPLE!G18 -> 589 | P23: ='Sheldon Elementary'!C18 -> 0.9595 | Q23: ='Sheldon Elementary'!D18 -> 593 | R23: =SLE!C18 -> 0.9742 | S23: =SLE!G18 -> 619 | T23: =CECA!C18 -> 0.9413 | U23: =CECA!G18 -> 531 | V23: =SECA!C18 -> 0.9465 | W23: =SECA!G18 -> 552 | X23: =KHS!C18 -> 0.9437 | Y23: =KHS!G18 -> 2614 | Z23: ='9TH CAMP'!C18 -> 0.9429 | AA23: ='9TH CAMP'!G18 -> 595 | AB23: =ECHS!C18 -> 0.9561 | AC23: =ECHS!G18 -> 457 | AD23: =KMS!C18 -> 0.9629 | AE23: =KMS!G18 -> 1348 | AF23: =NMS!C18 -> 0.9374 | AG23: =NMS!G18 -> 1038 | AH23: =Highpoint!C17 -> 0 | AI23: =KASE!D15 -> 97 | AK23: =AVERAGE(H23,J23,L23,N23,P23,R23,T23,V23,X23,Z23,AB23,AD23,AF23) -> 0.95526923
B24: =B23+450 -> 5850 | C24: Day 13 | D24: 45532 | E24: Wednesday | G24: =I24+K24+M24+O24+Q24+S24+U24+W24+Y24+AA24+AC24+AE24+AG24+AI24+AH24 -> 10799 | H24: =CE!C19 -> 0.9572 | I24: =CE!G19 -> 538 | J24: =GE!C19 -> 0.9404 | K24: =GE!G19 -> 604 | L24: =ME!C19 -> 0.9595 | M24: =ME!G19 -> 618 | N24: =SAMPLE!C19 -> 0.9559 | O24: =SAMPLE!G19 -> 589 | P24: ='Sheldon Elementary'!C19 -> 0.9612 | Q24: ='Sheldon Elementary'!D19 -> 593 | R24: =SLE!C19 -> 0.9626 | S24: =SLE!G19 -> 620 | T24: =CECA!C19 -> 0.9394 | U24: =CECA!G19 -> 535 | V24: =SECA!C19 -> 0.9148 | W24: =SECA!G19 -> 555 | X24: =KHS!C19 -> 0.9495 | Y24: =KHS!G19 -> 2612 | Z24: ='9TH CAMP'!C19 -> 0.953 | AA24: ='9TH CAMP'!G19 -> 596 | AB24: =ECHS!C19 -> 0.9715 | AC24: =ECHS!G19 -> 456 | AD24: =KMS!C19 -> 0.9644 | AE24: =KMS!G19 -> 1348 | AF24: =NMS!C19 -> 0.947 | AG24: =NMS!G19 -> 1038 | AH24: =Highpoint!C18 -> 0 | AI24: =KASE!D16 -> 97 | AK24: =AVERAGE(H24,J24,L24,N24,P24,R24,T24,V24,X24,Z24,AB24,AD24,AF24) -> 0.95203077
... B26: =B25+450 -> 6750 | C26: Day 15 | D26: 45534 | E26: Friday | G26: =I26+K26+M26+O26+Q26+S26+U26+W26+Y26+AA26+AC26+AE26+AG26+AI26+AH26 -> 10816 | H26: =CE!C21 -> 0.9459 | I26: =CE!G21 -> 536 | J26: =GE!C21 -> 0.9272 | K26: =GE!G21 -> 604 | L26: =ME!C21 -> 0.9389 | M26: =ME!G21 -> 622 | N26: =SAMPLE!C21 -> 0.9627 | O26: =SAMPLE!G21 -> 590 | P26: ='Sheldon Elementary'!C21 -> 0.9359 | Q26: ='Sheldon Elementary'!D21 -> 593 | R26: =SLE!C21 -> 0.9468 | S26: =SLE!G21 -> 620 | T26: =CECA!C21 -> 0.909 | U26: =CECA!G21 -> 535 | V26: =SECA!C21 -> 0.8245 | W26: =SECA!G21 -> 556 | X26: =KHS!C21 -> 0.9347 | Y26: =KHS!G21 -> 2620 | Z26: ='9TH CAMP'!C21 -> 0.9048 | AA26: ='9TH CAMP'!G21 -> 599 | AB26: =ECHS!C21 -> 0.9649 | AC26: =ECHS!G21 -> 456 | AD26: =KMS!C21 -> 0.9466 | AE26: =KMS!G21 -> 1348 | AF26: =NMS!C21 -> 0.9327 | AG26: =NMS!G21 -> 1040 | AH26: =Highpoint!C20 -> 0 | AI26: =KASE!D18 -> 97 | AK26: =AVERAGE(H26,J26,L26,N26,P26,R26,T26,V26,X26,Z26,AB26,AD26,AF26) -> 0.92881538
A27: HOLIDAY | D27: 45537 | E27: Monday | AK27: =AVERAGE(H27,J27,L27,N27,P27,R27,T27,V27,X27,Z27,AB27,AD27,AF27) -> #DIV/0!
B28: =B26+450 -> 7200 | C28: Day 16 | D28: 45538 | E28: Tuesday | G28: =I28+K28+M28+O28+Q28+S28+U28+W28+Y28+AA28+AC28+AE28+AG28+AI28+AH28 -> 10845 | H28: =CE!C23 -> 0.9493 | I28: =CE!G23 -> 533 | J28: =GE!C23 -> 0.9423 | K28: =GE!G23 -> 607 | L28: =ME!C23 -> 0.9565 | M28: =ME!G23 -> 621 | N28: =SAMPLE!C23 -> 0.9576 | O28: =SAMPLE!G23 -> 598 | P28: ='Sheldon Elementary'!C23 -> 0.9327 | Q28: ='Sheldon Elementary'!D23 -> 594 | R28: =SLE!C23 -> 0.9583 | S28: =SLE!G23 -> 624 | T28: =CECA!C23 -> 0.9157 | U28: =CECA!G23 -> 542 | V28: =SECA!C23 -> 0.8897 | W28: =SECA!G23 -> 548 | X28: =KHS!C23 -> 0.939 | Y28: =KHS!G23 -> 2625 | Z28: ='9TH CAMP'!C23 -> 0.9533 | AA28: ='9TH CAMP'!G23 -> 599 | AB28: =ECHS!C23 -> 0.9649 | AC28: =ECHS!G23 -> 456 | AD28: =KMS!C23 -> 0.9528 | AE28: =KMS!G23 -> 1357 | AF28: =NMS!C23 -> 0.9511 | AG28: =NMS!G23 -> 1044 | AH28: =Highpoint!C22 -> 0 | AI28: =KASE!D20 -> 97 | AK28: =AVERAGE(H28,J28,L28,N28,P28,R28,T28,V28,X28,Z28,AB28,AD28,AF28) -> 0.94332308
B29: =B28+450 -> 7650 | C29: Day 17 | D29: 45539 | E29: Wednesday | G29: =I29+K29+M29+O29+Q29+S29+U29+W29+Y29+AA29+AC29+AE29+AG29+AI29+AH29 -> 10845 | H29: =CE!C24 -> 0.9605 | I29: =CE!G24 -> 532 | J29: =GE!C24 -> 0.9555 | K29: =GE!G24 -> 607 | L29: =ME!C24 -> 0.9647 | M29: =ME!G24 -> 623 | N29: =SAMPLE!C24 -> 0.9728 | O29: =SAMPLE!G24 -> 588 | P29: ='Sheldon Elementary'!C24 -> 0.9613 | Q29: ='Sheldon Elementary'!D24 -> 595 | R29: =SLE!C24 -> 0.9711 | S29: =SLE!G24 -> 622 | T29: =CECA!C24 -> 0.9199 | U29: =CECA!G24 -> 547 | V29: =SECA!C24 -> 0.9183 | W29: =SECA!G24 -> 551 | X29: =KHS!C24 -> 0.9455 | Y29: =KHS!G24 -> 2626 | Z29: ='9TH CAMP'!C24 -> 0.945 | AA29: ='9TH CAMP'!G24 -> 600 | AB29: =ECHS!C24 -> 0.9649 | AC29: =ECHS!G24 -> 456 | AD29: =KMS!C24 -> 0.9646 | AE29: =KMS!G24 -> 1357 | AF29: =NMS!C24 -> 0.9589 | AG29: =NMS!G24 -> 1044 | AH29: =Highpoint!C23 -> 0 | AI29: =KASE!D21 -> 97 | AK29: =AVERAGE(H29,J29,L29,N29,P29,R29,T29,V29,X29,Z29,AB29,AD29,AF29) -> 0.95407692
B30: =B29+450 -> 8100 | C30: Day 18 | D30: 45540 | E30: Thursday | G30: =I30+K30+M30+O30+Q30+S30+U30+W30+Y30+AA30+AC30+AE30+AG30+AI30+AH30 -> 10852 | H30: =CE!C25 -> 0.9586 | I30: =CE!G25 -> 532 | J30: =GE!C25 -> 0.9539 | K30: =GE!G25 -> 608 | L30: =ME!C25 -> 0.9663 | M30: =ME!G25 -> 623 | N30: =SAMPLE!C25 -> 0.9525 | O30: =SAMPLE!G25 -> 589 | P30: ='Sheldon Elementary'!C25 -> 0.9562 | Q30: ='Sheldon Elementary'!D25 -> 594 | R30: =SLE!C25 -> 0.9727 | S30: =SLE!G25 -> 622 | T30: =CECA!C25 -> 0.9441 | U30: =CECA!G25 -> 547 | V30: =SECA!C25 -> 0.9403 | W30: =SECA!G25 -> 553 | X30: =KHS!C25 -> 0.9441 | Y30: =KHS!G25 -> 2632 | Z30: ='9TH CAMP'!C25 -> 0.94 | AA30: ='9TH CAMP'!G25 -> 600 | AB30: =ECHS!C25 -> 0.9846 | AC30: =ECHS!G25 -> 455 | AD30: =KMS!C25 -> 0.9603 | AE30: =KMS!G25 -> 1359 | AF30: =NMS!C25 -> 0.9501 | AG30: =NMS!G25 -> 1042 | AH30: =Highpoint!C24 -> 0 | AI30: =KASE!D22 -> 96 | AK30: =AVERAGE(H30,J30,L30,N30,P30,R30,T30,V30,X30,Z30,AB30,AD30,AF30) -> 0.95566923
B31: =B30+450 -> 8550 | C31: Day 19 | D31: 45541 | E31: Friday | G31: =I31+K31+M31+O31+Q31+S31+U31+W31+Y31+AA31+AC31+AE31+AG31+AI31+AH31 -> 10856 | H31: =CE!C26 -> 0.9193 | I31: =CE!G26 -> 533 | J31: =GE!C26 -> 0.9391 | K31: =GE!G26 -> 608 | L31: =ME!C26 -> 0.9487 | M31: =ME!G26 -> 624 | N31: =SAMPLE!C26 -> 0.969 | O31: =SAMPLE!G26 -> 589 | P31: ='Sheldon Elementary'!C26 -> 0.9528 | Q31: ='Sheldon Elementary'!D26 -> 593 | R31: =SLE!C26 -> 0.9515 | S31: =SLE!G26 -> 622 | T31: =CECA!C26 -> 0.9146 | U31: =CECA!G26 -> 548 | V31: =SECA!C26 -> 0.9066 | W31: =SECA!G26 -> 553 | X31: =KHS!C26 -> 0.9176 | Y31: =KHS!G26 -> 2633 | Z31: ='9TH CAMP'!C26 -> 0.9318 | AA31: ='9TH CAMP'!G26 -> 601 | AB31: =ECHS!C26 -> 0.9604 | AC31: =ECHS!G26 -> 455 | AD31: =KMS!C26 -> 0.9479 | AE31: =KMS!G26 -> 1362 | AF31: =NMS!C26 -> 0.9452 | AG31: =NMS!G26 -> 1040 | AH31: =Highpoint!C25 -> 0 | AI31: =KASE!D23 -> 95 | AK31: =AVERAGE(H31,J31,L31,N31,P31,R31,T31,V31,X31,Z31,AB31,AD31,AF31) -> 0.93880769
B32: =B31+450 -> 9000 | C32: Day 20 | D32: 45544 | E32: Monday | G32: =I32+K32+M32+O32+Q32+S32+U32+W32+Y32+AA32+AC32+AE32+AG32+AI32+AH32 -> 10866 | H32: =CE!C27 -> 0.9606 | I32: =CE!G27 -> 533 | J32: =GE!C27 -> 0.9391 | K32: =GE!G27 -> 608 | L32: =ME!C27 -> 0.949 | M32: =ME!G27 -> 628 | N32: =SAMPLE!C27 -> 0.951 | O32: =SAMPLE!G27 -> 592 | P32: ='Sheldon Elementary'!C27 -> 0.9695 | Q32: ='Sheldon Elementary'!D27 -> 591 | R32: =SLE!C27 -> 0.9583 | S32: =SLE!G27 -> 623 | T32: =CECA!C27 -> 0.9362 | U32: =CECA!G27 -> 548 | V32: =SECA!C27 -> 0.9197 | W32: =SECA!G27 -> 553 | X32: =KHS!C27 -> 0.9419 | Y32: =KHS!G27 -> 2633 | Z32: ='9TH CAMP'!C27 -> 0.9554 | AA32: ='9TH CAMP'!G27 -> 605 | AB32: =ECHS!C27 -> 0.9714 | AC32: =ECHS!G27 -> 455 | AD32: =KMS!C27 -> 0.9655 | AE32: =KMS!G27 -> 1361 | AF32: =NMS!C27 -> 0.951 | AG32: =NMS!G27 -> 1040 | AH32: =Highpoint!C26 -> 0 | AI32: =KASE!D24 -> 96 | AK32: =AVERAGE(H32,J32,L32,N32,P32,R32,T32,V32,X32,Z32,AB32,AD32,AF32) -> 0.95143077
B33: =B32+450 -> 9450 | C33: Day 21 | D33: 45545 | E33: Tuesday | G33: =I33+K33+M33+O33+Q33+S33+U33+W33+Y33+AA33+AC33+AE33+AG33+AI33+AH33 -> 10883 | H33: =CE!C28 -> 0.9606 | I33: =CE!G28 -> 533 | J33: =GE!C28 -> 0.9622 | K33: =GE!G28 -> 607 | L33: =ME!C28 -> 0.949 | M33: =ME!G28 -> 628 | N33: =SAMPLE!C28 -> 0.9429 | O33: =SAMPLE!G28 -> 595 | P33: ='Sheldon Elementary'!C28 -> 0.9542 | Q33: ='Sheldon Elementary'!D28 -> 590 | R33: =SLE!C28 -> 0.9585 | S33: =SLE!G28 -> 627 | T33: =CECA!C28 -> 0.934 | U33: =CECA!G28 -> 549 | V33: =SECA!C28 -> 0.9273 | W33: =SECA!G28 -> 554 | X33: =KHS!C28 -> 0.9447 | Y33: =KHS!G28 -> 2638 | Z33: ='9TH CAMP'!C28 -> 0.9409 | AA33: ='9TH CAMP'!G28 -> 609 | AB33: =ECHS!C28 -> 0.9758 | AC33: =ECHS!G28 -> 455 | AD33: =KMS!C28 -> 0.9662 | AE33: =KMS!G28 -> 1361 | AF33: =NMS!C28 -> 0.9663 | AG33: =NMS!G28 -> 1041 | AH33: =Highpoint!C27 -> 0 | AI33: =KASE!D25 -> 96 | AK33: =AVERAGE(H33,J33,L33,N33,P33,R33,T33,V33,X33,Z33,AB33,AD33,AF33) -> 0.95250769
B34: =B33+450 -> 9900 | C34: Day 22 | D34: 45546 | E34: Wednesday | G34: =I34+K34+M34+O34+Q34+S34+U34+W34+Y34+AA34+AC34+AE34+AG34+AI34+AH34 -> 10894 | H34: =CE!C29 -> 0.9607 | I34: =CE!G29 -> 534 | J34: =GE!C29 -> 0.9557 | K34: =GE!G29 -> 609 | L34: =ME!C29 -> 0.9522 | M34: =ME!G29 -> 628 | N34: =SAMPLE!C29 -> 0.9412 | O34: =SAMPLE!G29 -> 595 | P34: ='Sheldon Elementary'!C29 -> 0.9492 | Q34: ='Sheldon Elementary'!D29 -> 590 | R34: =SLE!C29 -> 0.9522 | S34: =SLE!G29 -> 627 | T34: =CECA!C29 -> 0.9278 | U34: =CECA!G29 -> 554 | V34: =SECA!C29 -> 0.9207 | W34: =SECA!G29 -> 553 | X34: =KHS!C29 -> 0.9416 | Y34: =KHS!G29 -> 2638 | Z34: ='9TH CAMP'!C29 -> 0.9245 | AA34: ='9TH CAMP'!G29 -> 609 | AB34: =ECHS!C29 -> 0.978 | AC34: =ECHS!G29 -> 455 | AD34: =KMS!C29 -> 0.9574 | AE34: =KMS!G29 -> 1362 | AF34: =NMS!C29 -> 0.9482 | AG34: =NMS!G29 -> 1041 | AH34: =Highpoint!C28 -> 0 | AI34: =KASE!D26 -> 99 | AK34: =AVERAGE(H34,J34,L34,N34,P34,R34,T34,V34,X34,Z34,AB34,AD34,AF34) -> 0.94687692
B35: =B34+450 -> 10350 | C35: Day 23 | D35: 45547 | E35: Thursday | G35: =I35+K35+M35+O35+Q35+S35+U35+W35+Y35+AA35+AC35+AE35+AG35+AI35+AH35 -> 10895 | H35: =CE!C30 -> 0.9663 | I35: =CE!G30 -> 534 | J35: =GE!C30 -> 0.9541 | K35: =GE!G30 -> 610 | L35: =ME!C30 -> 0.9697 | M35: =ME!G30 -> 627 | N35: =SAMPLE!C30 -> 0.958 | O35: =SAMPLE!G30 -> 595 | P35: ='Sheldon Elementary'!C30 -> 0.9644 | Q35: ='Sheldon Elementary'!D30 -> 590 | R35: =SLE!C30 -> 0.9617 | S35: =SLE!G30 -> 627 | T35: =CECA!C30 -> 0.9438 | U35: =CECA!G30 -> 555 | V35: =SECA!C30 -> 0.9141 | W35: =SECA!G30 -> 553 | X35: =KHS!C30 -> 0.9522 | Y35: =KHS!G30 -> 2637 | Z35: ='9TH CAMP'!C30 -> 0.9475 | AA35: ='9TH CAMP'!G30 -> 609 | AB35: =ECHS!C30 -> 0.9736 | AC35: =ECHS!G30 -> 455 | AD35: =KMS!C30 -> 0.9633 | AE35: =KMS!G30 -> 1363 | AF35: =NMS!C30 -> 0.9482 | AG35: =NMS!G30 -> 1041 | AH35: =Highpoint!C29 -> 0 | AI35: =KASE!D27 -> 99 | AK35: =AVERAGE(H35,J35,L35,N35,P35,R35,T35,V35,X35,Z35,AB35,AD35,AF35) -> 0.95514615
B36: =B35+450 -> 10800 | C36: Day 24 | D36: 45548 | E36: Friday | G36: =I36+K36+M36+O36+Q36+S36+U36+W36+Y36+AA36+AC36+AE36+AG36+AI36+AH36 -> 10893 | H36: =CE!C31 -> 0.9438 | I36: =CE!G31 -> 534 | J36: =GE!C31 -> 0.9475 | K36: =GE!G31 -> 610 | L36: =ME!C31 -> 0.9442 | M36: =ME!G31 -> 627 | N36: =SAMPLE!C31 -> 0.9563 | O36: =SAMPLE!G31 -> 595 | P36: ='Sheldon Elementary'!C31 -> 0.9475 | Q36: ='Sheldon Elementary'!D31 -> 590 | R36: =SLE!C31 -> 0.9601 | S36: =SLE!G31 -> 626 | T36: =CECA!C31 -> 0.9131 | U36: =CECA!G31 -> 553 | V36: =SECA!C31 -> 0.8969 | W36: =SECA!G31 -> 554 | X36: =KHS!C31 -> 0.92 | Y36: =KHS!G31 -> 2636 | Z36: ='9TH CAMP'!C31 -> 0.8869 | AA36: ='9TH CAMP'!G31 -> 610 | AB36: =ECHS!C31 -> 0.9626 | AC36: =ECHS!G31 -> 455 | AD36: =KMS!C31 -> 0.9405 | AE36: =KMS!G31 -> 1362 | AF36: =NMS!C31 -> 0.9394 | AG36: =NMS!G31 -> 1041 | AH36: =Highpoint!C30 -> 0 | AI36: =KASE!D28 -> 100 | AK36: =AVERAGE(H36,J36,L36,N36,P36,R36,T36,V36,X36,Z36,AB36,AD36,AF36) -> 0.93529231
A37: PD DAY | D37: 45551 | E37: Monday | H37: =CE!C32 -> 0 | AK37: =AVERAGE(H37,J37,L37,N37,P37,R37,T37,V37,X37,Z37,AB37,AD37,AF37) -> 0
B38: =B36+450 -> 11250 | C38: Day 25 | D38: 45552 | E38: Tuesday | G38: =I38+K38+M38+O38+Q38+S38+U38+W38+Y38+AA38+AC38+AE38+AG38+AI38+AH38 -> 10909 | H38: =CE!C33 -> 0.9627 | I38: =CE!G33 -> 536 | J38: =GE!C33 -> 0.9671 | K38: =GE!G33 -> 607 | L38: =ME!C33 -> 0.9825 | M38: =ME!G33 -> 630 | N38: =SAMPLE!C33 -> 0.9599 | O38: =SAMPLE!G33 -> 598 | P38: ='Sheldon Elementary'!C33 -> 0.961 | Q38: ='Sheldon Elementary'!D33 -> 589 | R38: =SLE!C33 -> 0.9571 | S38: =SLE!G33 -> 628 | T38: =CECA!C33 -> 0.9438 | U38: =CECA!G33 -> 554 | V38: =SECA!C33 -> 0.9001 | W38: =SECA!G33 -> 555 | X38: =KHS!C33 -> 0.9428 | Y38: =KHS!G33 -> 2641 | Z38: ='9TH CAMP'!C33 -> 0.9444 | AA38: ='9TH CAMP'!G33 -> 611 | AB38: =ECHS!C33 -> 0.9802 | AC38: =ECHS!G33 -> 455 | AD38: =KMS!C33 -> 0.9596 | AE38: =KMS!G33 -> 1362 | AF38: =NMS!C33 -> 0.9587 | AG38: =NMS!G33 -> 1042 | AH38: =Highpoint!C32 -> 0 | AI38: =KASE!D30 -> 101 | AK38: =AVERAGE(H38,J38,L38,N38,P38,R38,T38,V38,X38,Z38,AB38,AD38,AF38) -> 0.95537692
B39: =B38+450 -> 11700 | C39: Day 26 | D39: 45553 | E39: Wednesday | G39: =I39+K39+M39+O39+Q39+S39+U39+W39+Y39+AA39+AC39+AE39+AG39+AI39+AH39 -> 10908 | H39: =CE!C34 -> 0.9757 | I39: =CE!G34 -> 536 | J39: =GE!C34 -> 0.9638 | K39: =GE!G34 -> 607 | L39: =ME!C34 -> 0.9825 | M39: =ME!G34 -> 630 | N39: =SAMPLE!C34 -> 0.9649 | O39: =SAMPLE!G34 -> 598 | P39: ='Sheldon Elementary'!C34 -> 0.9745 | Q39: ='Sheldon Elementary'!D34 -> 589 | R39: =SLE!C34 -> 0.9682 | S39: =SLE!G34 -> 628 | T39: =CECA!C34 -> 0.9245 | U39: =CECA!G34 -> 554 | V39: =SECA!C34 -> 0.9 | W39: =SECA!G34 -> 555 | X39: =KHS!C34 -> 0.9375 | Y39: =KHS!G34 -> 2641 | Z39: ='9TH CAMP'!C34 -> 0.9345 | AA39: ='9TH CAMP'!G34 -> 611 | AB39: =ECHS!C34 -> 0.9714 | AC39: =ECHS!G34 -> 455 | AD39: =KMS!C34 -> 0.9647 | AE39: =KMS!G34 -> 1361 | AF39: =NMS!C34 -> 0.9501 | AG39: =NMS!G34 -> 1042 | AH39: =Highpoint!C33 -> 0 | AI39: =KASE!D31 -> 101 | AK39: =AVERAGE(H39,J39,L39,N39,P39,R39,T39,V39,X39,Z39,AB39,AD39,AF39) -> 0.95479231
B40: =B39+450 -> 12150 | C40: Day 27 | D40: 45554 | E40: Thursday | G40: =I40+K40+M40+O40+Q40+S40+U40+W40+Y40+AA40+AC40+AE40+AG40+AI40+AH40 -> 10908 | H40: =CE!C35 -> 0.9683 | I40: =CE!G35 -> 536 | J40: =GE!C35 -> 0.9555 | K40: =GE!G35 -> 607 | L40: =ME!C35 -> 0.9667 | M40: =ME!G35 -> 630 | N40: =SAMPLE!C35 -> 0.9482 | O40: =SAMPLE!G35 -> 598 | P40: ='Sheldon Elementary'!C35 -> 0.9593 | Q40: ='Sheldon Elementary'!D35 -> 589 | R40: =SLE!C35 -> 0.9555 | S40: =SLE!G35 -> 628 | T40: =CECA!C35 -> 0.9122 | U40: =CECA!G35 -> 554 | V40: =SECA!C35 -> 0.8958 | W40: =SECA!G35 -> 555 | X40: =KHS!C35 -> 0.9375 | Y40: =KHS!G35 -> 2641 | Z40: ='9TH CAMP'!C35 -> 0.9296 | AA40: ='9TH CAMP'!G35 -> 611 | AB40: =ECHS!C35 -> 0.9692 | AC40: =ECHS!G35 -> 455 | AD40: =KMS!C35 -> 0.9721 | AE40: =KMS!G35 -> 1361 | AF40: =NMS!C35 -> 0.9415 | AG40: =NMS!G35 -> 1042 | AH40: =Highpoint!C34 -> 0 | AI40: =KASE!D32 -> 101 | AK40: =AVERAGE(H40,J40,L40,N40,P40,R40,T40,V40,X40,Z40,AB40,AD40,AF40) -> 0.94703077
B41: =B40+450 -> 12600 | C41: Day 28 | D41: 45555 | E41: Friday | G41: =I41+K41+M41+O41+Q41+S41+U41+W41+Y41+AA41+AC41+AE41+AG41+AI42+AH41 -> 10903 | H41: =CE!C36 -> 0.9366 | I41: =CE!G36 -> 536 | J41: =GE!C36 -> 0.8896 | K41: =GE!G36 -> 606 | L41: =ME!C36 -> 0.9413 | M41: =ME!G36 -> 630 | N41: =SAMPLE!C36 -> 0.9529 | O41: =SAMPLE!G36 -> 595 | P41: ='Sheldon Elementary'!C36 -> 0.944 | Q41: ='Sheldon Elementary'!D36 -> 589 | R41: =SLE!C36 -> 0.9475 | S41: =SLE!G36 -> 628 | T41: =CECA!C36 -> 0.9292 | U41: =CECA!G36 -> 555 | V41: =SECA!C36 -> 0.8915 | W41: =SECA!G36 -> 556 | X41: =KHS!C36 -> 0.9201 | Y41: =KHS!G36 -> 2641 | Z41: ='9TH CAMP'!C36 -> 0.9231 | AA41: ='9TH CAMP'!G36 -> 611 | AB41: =ECHS!C36 -> 0.9607 | AC41: =ECHS!G36 -> 455 | AD41: =KMS!C36 -> 0.955 | AE41: =KMS!G36 -> 1357 | AF41: =NMS!C36 -> 0.777 | AG41: =NMS!G36 -> 1043 | AH41: =Highpoint!C35 -> 0 | AI41: =KASE!D33 -> 101 | AK41: =AVERAGE(H41,J41,L41,N41,P41,R41,T41,V41,X41,Z41,AB41,AD41,AF41) -> 0.92065385
...

Sheet SECA
K1: =SUM(K7:K215) -> -2470.1384
A2: SHELDON ECA | H2: Estimated $ Missed Annually | J2: District Goal | K2: Campus Teams HIGHLIGHTED CELLS INDICATE # OF STUDENTS ABSENT ABOVE DISTRICT GOAL
H3: =SUM(I7:I128) -> 234562.56 | J3: 0.95
H4: Estimated $ Per Student
H5: 55
A6: Date | B6: Day of the Week | C6: Campus ADA % | D6: Is ADA Below 90%? (Yes/No) | E6: If "Yes" Give Reason | F6: Explain if "Other" | G6: Enrollment | H6: # Students Absent | I6: Estimated $ Missed | J6: DISTRICTS # ABS GOAL
A7: 45516 | B7: Monday | C7: 1 | D7: NO | G7: 464 | H7: =G7-(C7*G7) -> 0 | I7: =H7*$H$5 -> 0 | J7: 0 | K7: =J7-H7 -> 0
A8: 45517 | B8: Tuesday | C8: 0.9886 | D8: NO | G8: 487 | H8: =G8-(C8*G8) -> 5.5518 | I8: =H8*$H$5 -> 305.349 | J8: =G8-(G8*J$3) -> 24.35 | K8: =J8-H8 -> 18.7982
A9: 45518 | B9: Wednesday | C9: 0.9809 | D9: NO | G9: 495 | H9: =G9-(C9*G9) -> 9.4545 | I9: =H9*$H$5 -> 519.9975 | J9: =G9-(G9*J$3) -> 24.75 | K9: =J9-H9 -> 15.2955
A10: 45519 | B10: Thursday | C10: 0.946 | D10: NO | G10: 503 | H10: =G10-(C10*G10) -> 27.162 | I10: =H10*$H$5 -> 1493.91 | J10: =G10-(G10*J$3) -> 25.15 | K10: =J10-H10 -> -2.012
A11: 45520 | B11: Friday | C11: 0.9242 | D11: NO | G11: 515 | H11: =G11-(C11*G11) -> 39.037 | I11: =H11*$H$5 -> 2147.035 | J11: =G11-(G11*J$3) -> 25.75 | K11: =J11-H11 -> -13.287
A12: 45523 | B12: Monday | C12: 0.9063 | D12: NO | G12: 529 | H12: =G12-(C12*G12) -> 49.5673 | I12: =H12*$H$5 -> 2726.2015 | J12: =G12-(G12*J$3) -> 26.45 | K12: =J12-H12 -> -23.1173
A13: 45524 | B13: Tuesday | C13: 0.9302 | D13: NO | G13: 535 | H13: =G13-(C13*G13) -> 37.343 | I13: =H13*$H$5 -> 2053.865 | J13: =G13-(G13*J$3) -> 26.75 | K13: =J13-H13 -> -10.593
A14: 45525 | B14: Wednesday | C14: 0.9352 | D14: no | G14: 540 | H14: =G14-(C14*G14) -> 34.992 | I14: =H14*$H$5 -> 1924.56 | J14: =G14-(G14*J$3) -> 27 | K14: =J14-H14 -> -7.992
A15: 45526 | B15: Thursday | C15: 0.9316 | D15: NO | G15: 544 | H15: =G15-(C15*G15) -> 37.2096 | I15: =H15*$H$5 -> 2046.528 | J15: =G15-(G15*J$3) -> 27.2 | K15: =J15-H15 -> -10.0096
A16: 45527 | B16: Friday | C16: 0.9234 | D16: NO | G16: 546 | H16: =G16-(C16*G16) -> 41.8236 | I16: =H16*$H$5 -> 2300.298 | J16: =G16-(G16*J$3) -> 27.3 | K16: =J16-H16 -> -14.5236
A17: 45530 | B17: Monday | C17: 0.9096 | D17: NO | G17: 549 | H17: =G17-(C17*G17) -> 49.6296 | I17: =H17*$H$5 -> 2729.628 | J17: =G17-(G17*J$3) -> 27.45 | K17: =J17-H17 -> -22.1796
A18: 45531 | B18: Tuesday | C18: 0.9465 | D18: NO | G18: 552 | H18: =G18-(C18*G18) -> 29.532 | I18: =H18*$H$5 -> 1624.26 | J18: =G18-(G18*J$3) -> 27.6 | K18: =J18-H18 -> -1.932
A19: 45532 | B19: Wednesday | C19: 0.9148 | D19: NO | G19: 555 | H19: =G19-(C19*G19) -> 47.286 | I19: =H19*$H$5 -> 2600.73 | J19: =G19-(G19*J$3) -> 27.75 | K19: =J19-H19 -> -19.536
A20: 45533 | B20: Thursday | C20: 0.9073 | D20: NO | G20: 556 | H20: =G20-(C20*G20) -> 51.5412 | I20: =H20*$H$5 -> 2834.766 | J20: =G20-(G20*J$3) -> 27.8 | K20: =J20-H20 -> -23.7412
A21: 45534 | B21: Friday | C21: 0.8245 | D21: yes | E21: Health | F21: many student had the flu, covid,upset stomach. | G21: 556 | H21: =G21-(C21*G21) -> 97.578 | I21: =H21*$H$5 -> 5366.79 | J21: =G21-(G21*J$3) -> 27.8 | K21: =J21-H21 -> -69.778
A22: 45537 | B22: Monday | H22: =G22-(C22*G22) -> 0 | I22: =H22*$H$5 -> 0 | J22: =G22-(G22*J$3) -> 0 | K22: =J22-H22 -> 0
A23: 45538 | B23: Tuesday | C23: 0.8897 | D23: yes | E23: Health | F23: flu, common colds. | G23: 548 | H23: =G23-(C23*G23) -> 60.4444 | I23: =H23*$H$5 -> 3324.442 | J23: =G23-(G23*J$3) -> 27.4 | K23: =J23-H23 -> -33.0444
A24: 45539 | B24: Wednesday | C24: 0.9183 | D24: yes | E24: Health | F24: colds, flu | G24: 551 | H24: =G24-(C24*G24) -> 45.0167 | I24: =H24*$H$5 -> 2475.9185 | J24: =G24-(G24*J$3) -> 27.55 | K24: =J24-H24 -> -17.4667
A25: 45540 | B25: Thursday | C25: 0.9403 | D25: no | G25: 553 | H25: =G25-(C25*G25) -> 33.0141 | I25: =H25*$H$5 -> 1815.7755 | J25: =G25-(G25*J$3) -> 27.65 | K25: =J25-H25 -> -5.3641
A26: 45541 | B26: Friday | C26: 0.9066 | D26: NO | G26: 553 | H26: =G26-(C26*G26) -> 51.6502 | I26: =H26*$H$5 -> 2840.761 | J26: =G26-(G26*J$3) -> 27.65 | K26: =J26-H26 -> -24.0002
A27: 45544 | B27: Monday | C27: 0.9197 | D27: NO | G27: 553 | H27: =G27-(C27*G27) -> 44.4059 | I27: =H27*$H$5 -> 2442.3245 | J27: =G27-(G27*J$3) -> 27.65 | K27: =J27-H27 -> -16.7559
A28: 45545 | B28: Tuesday | C28: 0.9273 | D28: NO | G28: 554 | H28: =G28-(C28*G28) -> 40.2758 | I28: =H28*$H$5 -> 2215.169 | J28: =G28-(G28*J$3) -> 27.7 | K28: =J28-H28 -> -12.5758
A29: 45546 | B29: Wednesday | C29: 0.9207 | D29: no | G29: 553 | H29: =G29-(C29*G29) -> 43.8529 | I29: =H29*$H$5 -> 2411.9095 | J29: =G29-(G29*J$3) -> 27.65 | K29: =J29-H29 -> -16.2029
A30: 45547 | B30: Thursday | C30: 0.9141 | D30: NO | G30: 553 | H30: =G30-(C30*G30) -> 47.5027 | I30: =H30*$H$5 -> 2612.6485 | J30: =G30-(G30*J$3) -> 27.65 | K30: =J30-H30 -> -19.8527
A31: 45548 | B31: Friday | C31: 0.8969 | D31: YES | E31: Other | F31: Low attendance on fridays | G31: 554 | H31: =G31-(C31*G31) -> 57.1174 | I31: =H31*$H$5 -> 3141.457 | J31: =G31-(G31*J$3) -> 27.7 | K31: =J31-H31 -> -29.4174
A32: 45551 | B32: Monday | H32: =G32-(C32*G32) -> 0 | I32: =H32*$H$5 -> 0 | J32: =G32-(G32*J$3) -> 0 | K32: =J32-H32 -> 0
A33: 45552 | B33: Tuesday | C33: 0.9001 | D33: NO | G33: 555 | H33: =G33-(C33*G33) -> 55.4445 | I33: =H33*$H$5 -> 3049.4475 | J33: =G33-(G33*J$3) -> 27.75 | K33: =J33-H33 -> -27.6945
A34: 45553 | B34: Wednesday | C34: 0.9 | D34: NO | F34: ILLNESS | G34: 555 | H34: =G34-(C34*G34) -> 55.5 | I34: =H34*$H$5 -> 3052.5 | J34: =G34-(G34*J$3) -> 27.75 | K34: =J34-H34 -> -27.75
A35: 45554 | B35: Thursday | C35: 0.8958 | D35: yes | E35: Other | F35: illness | G35: 555 | H35: =G35-(C35*G35) -> 57.831 | I35: =H35*$H$5 -> 3180.705 | J35: =G35-(G35*J$3) -> 27.75 | K35: =J35-H35 -> -30.081
A36: 45555 | B36: Friday | C36: 0.8915 | D36: yes | E36: Other | F36: illness | G36: 556 | H36: =G36-(C36*G36) -> 60.326 | I36: =H36*$H$5 -> 3317.93 | J36: =G36-(G36*J$3) -> 27.8 | K36: =J36-H36 -> -32.526
A37: 45558 | B37: Monday | C37: 0.8915 | D37: YES | E37: Other | F37: unknown | G37: 556 | H37: =G37-(C37*G37) -> 60.326 | I37: =H37*$H$5 -> 3317.93 | J37: =G37-(G37*J$3) -> 27.8 | K37: =J37-H37 -> -32.526
A38: 45559 | B38: Tuesday | C38: 0.9328 | D38: NO | G38: 556 | H38: =G38-(C38*G38) -> 37.3632 | I38: =H38*$H$5 -> 2054.976 | J38: =G38-(G38*J$3) -> 27.8 | K38: =J38-H38 -> -9.5632
A39: 45560 | B39: Wednesday | C39: 0.9382 | D39: no | G39: 556 | H39: =G39-(C39*G39) -> 34.3608 | I39: =H39*$H$5 -> 1889.844 | J39: =G39-(G39*J$3) -> 27.8 | K39: =J39-H39 -> -6.5608
A40: 45561 | B40: Thursday | C40: 0.9177 | D40: NO | G40: 558 | H40: =G40-(C40*G40) -> 45.9234 | I40: =H40*$H$5 -> 2525.787 | J40: =G40-(G40*J$3) -> 27.9 | K40: =J40-H40 -> -18.0234
...

Sheet CECA
K1: =SUM(K7:K215) -> -2074.8579
A2: CRAVENS ECA | H2: Estimated $ Missed Annually | J2: District Goal | K2: Campus Teams HIGHLIGHTED CELLS INDICATE # OF STUDENTS ABSENT ABOVE DISTRICT GOAL
H3: =SUM(I7:I128) -> 219811 | J3: 0.95
H4: Estimated $ Per Student
H5: 55
A6: Date | B6: Day of the Week | C6: Campus ADA % | D6: Is ADA Below 90%? (Yes/No) | E6: If "Yes" Give Reason | F6: Explain if "Other" | G6: Enrollment | H6: # Students Absent | I6: Estimated $ Missed | J6: DISTRICTS # ABS GOAL
A7: 45516 | B7: Monday | C7: 1 | D7: N | G7: 472 | H7: =G7-(C7*G7) -> 0 | I7: =H7*$H$5 -> 0 | J7: 0 | K7: =J7-H7 -> 0
A8: 45517 | B8: Tuesday | C8: 0.9873 | D8: N | G8: 485 | H8: =G8-(C8*G8) -> 6.1595 | I8: =H8*$H$5 -> 338.7725 | J8: =G8-(G8*J$3) -> 24.25 | K8: =J8-H8 -> 18.0905
A9: 45518 | B9: Wednesday | C9: 0.9888 | D9: N | G9: 493 | H9: =G9-(C9*G9) -> 5.5216 | I9: =H9*$H$5 -> 303.688 | J9: =G9-(G9*J$3) -> 24.65 | K9: =J9-H9 -> 19.1284
A10: 45519 | B10: Thursday | C10: 0.9667 | D10: N | G10: 501 | H10: =G10-(C10*G10) -> 16.6833 | I10: =H10*$H$5 -> 917.5815 | J10: =G10-(G10*J$3) -> 25.05 | K10: =J10-H10 -> 8.3667
A11: 45520 | B11: Friday | C11: 0.9407 | D11: N | G11: 503 | H11: =G11-(C11*G11) -> 29.8279 | I11: =H11*$H$5 -> 1640.5345 | J11: =G11-(G11*J$3) -> 25.15 | K11: =J11-H11 -> -4.6779
A12: 45523 | B12: Monday | C12: 0.9329 | D12: N | G12: 509 | H12: =G12-(C12*G12) -> 34.1539 | I12: =H12*$H$5 -> 1878.4645 | J12: =G12-(G12*J$3) -> 25.45 | K12: =J12-H12 -> -8.7039
A13: 45524 | B13: Tuesday | C13: 0.9359 | D13: N | G13: 514 | H13: =G13-(C13*G13) -> 32.9474 | I13: =H13*$H$5 -> 1812.107 | J13: =G13-(G13*J$3) -> 25.7 | K13: =J13-H13 -> -7.2474
A14: 45525 | B14: Wednesday | C14: 0.9293 | D14: N | G14: 519 | H14: =G14-(C14*G14) -> 36.6933 | I14: =H14*$H$5 -> 2018.1315 | J14: =G14-(G14*J$3) -> 25.95 | K14: =J14-H14 -> -10.7433
A15: 45526 | B15: Thursday | C15: 0.9401 | D15: N | G15: 520 | H15: =G15-(C15*G15) -> 31.148 | I15: =H15*$H$5 -> 1713.14 | J15: =G15-(G15*J$3) -> 26 | K15: =J15-H15 -> -5.148
A16: 45527 | B16: Friday | C16: 0.92 | D16: N | G16: 523 | H16: =G16-(C16*G16) -> 41.84 | I16: =H16*$H$5 -> 2301.2 | J16: =G16-(G16*J$3) -> 26.15 | K16: =J16-H16 -> -15.69
A17: 45530 | B17: Monday | C17: 0.9308 | D17: N | G17: 532 | H17: =G17-(C17*G17) -> 36.8144 | I17: =H17*$H$5 -> 2024.792 | J17: =G17-(G17*J$3) -> 26.6 | K17: =J17-H17 -> -10.2144
A18: 45531 | B18: Tuesday | C18: 0.9413 | D18: N | G18: 531 | H18: =G18-(C18*G18) -> 31.1697 | I18: =H18*$H$5 -> 1714.3335 | J18: =G18-(G18*J$3) -> 26.55 | K18: =J18-H18 -> -4.6197
A19: 45532 | B19: Wednesday | C19: 0.9394 | D19: N | G19: 535 | H19: =G19-(C19*G19) -> 32.421 | I19: =H19*$H$5 -> 1783.155 | J19: =G19-(G19*J$3) -> 26.75 | K19: =J19-H19 -> -5.671
... A21: 45534 | B21: Friday | C21: 0.909 | D21: N | G21: 535 | H21: =G21-(C21*G21) -> 48.685 | I21: =H21*$H$5 -> 2677.675 | J21: =G21-(G21*J$3) -> 26.75 | K21: =J21-H21 -> -21.935
A22: 45537 | B22: Monday | H22: =G22-(C22*G22) -> 0 | I22: =H22*$H$5 -> 0 | J22: =G22-(G22*J$3) -> 0 | K22: =J22-H22 -> 0
A23: 45538 | B23: Tuesday | C23: 0.9157 | D23: N | G23: 542 | H23: =G23-(C23*G23) -> 45.6906 | I23: =H23*$H$5 -> 2512.983 | J23: =G23-(G23*J$3) -> 27.1 | K23: =J23-H23 -> -18.5906
A24: 45539 | B24: Wednesday | C24: 0.9199 | D24: N | G24: 547 | H24: =G24-(C24*G24) -> 43.8147 | I24: =H24*$H$5 -> 2409.8085 | J24: =G24-(G24*J$3) -> 27.35 | K24: =J24-H24 -> -16.4647
A25: 45540 | B25: Thursday | C25: 0.9441 | D25: N | G25: 547 | H25: =G25-(C25*G25) -> 30.5773 | I25: =H25*$H$5 -> 1681.7515 | J25: =G25-(G25*J$3) -> 27.35 | K25: =J25-H25 -> -3.2273
A26: 45541 | B26: Friday | C26: 0.9146 | D26: N | G26: 548 | H26: =G26-(C26*G26) -> 46.7992 | I26: =H26*$H$5 -> 2573.956 | J26: =G26-(G26*J$3) -> 27.4 | K26: =J26-H26 -> -19.3992
A27: 45544 | B27: Monday | C27: 0.9362 | D27: N | G27: 548 | H27: =G27-(C27*G27) -> 34.9624 | I27: =H27*$H$5 -> 1922.932 | J27: =G27-(G27*J$3) -> 27.4 | K27: =J27-H27 -> -7.5624
A28: 45545 | B28: Tuesday | C28: 0.934 | D28: N | G28: 549 | H28: =G28-(C28*G28) -> 36.234 | I28: =H28*$H$5 -> 1992.87 | J28: =G28-(G28*J$3) -> 27.45 | K28: =J28-H28 -> -8.784
A29: 45546 | B29: Wednesday | C29: 0.9278 | D29: N | G29: 554 | H29: =G29-(C29*G29) -> 39.9988 | I29: =H29*$H$5 -> 2199.934 | J29: =G29-(G29*J$3) -> 27.7 | K29: =J29-H29 -> -12.2988
A30: 45547 | B30: Thursday | C30: 0.9438 | D30: N | G30: 555 | H30: =G30-(C30*G30) -> 31.191 | I30: =H30*$H$5 -> 1715.505 | J30: =G30-(G30*J$3) -> 27.75 | K30: =J30-H30 -> -3.441
A31: 45548 | B31: Friday | C31: 0.9131 | D31: N | G31: 553 | H31: =G31-(C31*G31) -> 48.0557 | I31: =H31*$H$5 -> 2643.0635 | J31: =G31-(G31*J$3) -> 27.65 | K31: =J31-H31 -> -20.4057
A32: 45551 | B32: Monday | H32: =G32-(C32*G32) -> 0 | I32: =H32*$H$5 -> 0 | J32: =G32-(G32*J$3) -> 0 | K32: =J32-H32 -> 0
A33: 45552 | B33: Tuesday | C33: 0.9438 | D33: N | G33: 554 | H33: =G33-(C33*G33) -> 31.1348 | I33: =H33*$H$5 -> 1712.414 | J33: =G33-(G33*J$3) -> 27.7
A34: 45553 | B34: Wednesday | C34: 0.9245 | D34: N | G34: 554 | H34: =G34-(C34*G34) -> 41.827 | I34: =H34*$H$5 -> 2300.485 | J34: =G34-(G34*J$3) -> 27.7 | K34: =J34-H34 -> -14.127
A35: 45554 | B35: Thursday | C35: 0.9122 | D35: N | G35: 554 | H35: =G35-(C35*G35) -> 48.6412 | I35: =H35*$H$5 -> 2675.266 | J35: =G35-(G35*J$3) -> 27.7 | K35: =J35-H35 -> -20.9412
A36: 45555 | B36: Friday | C36: 0.9292 | D36: N | G36: 555 | H36: =G36-(C36*G36) -> 39.294 | I36: =H36*$H$5 -> 2161.17 | J36: =G36-(G36*J$3) -> 27.75 | K36: =J36-H36 -> -11.544
A37: 45558 | B37: Monday | C37: 0.9125 | D37: N | G37: 557 | H37: =G37-(C37*G37) -> 48.7375 | I37: =H37*$H$5 -> 2680.5625 | J37: =G37-(G37*J$3) -> 27.85 | K37: =J37-H37 -> -20.8875
A38: 45559 | B38: Tuesday | C38: 0.9429 | D38: N | G38: 558 | H38: =G37-(C38*G37) -> 31.8047 | I38: =H38*$H$5 -> 1749.2585 | J38: =G37-(G37*J$3) -> 27.85 | K38: =J38-H38 -> -3.9547
A39: 45560 | B39: Wednesday | C39: 0.9362 | D39: N | G39: 558 | H39: =G39-(C39*G39) -> 35.6004 | I39: =H39*$H$5 -> 1958.022 | J39: =G39-(G39*J$3) -> 27.9 | K39: =J39-H39 -> -7.7004
A40: 45561 | B40: Thursday | C40: 0.9552 | D40: N | G40: 558 | H40: =G40-(C40*G40) -> 24.9984 | I40: =H40*$H$5 -> 1374.912 | J40: =G40-(G40*J$3) -> 27.9 | K40: =J40-H40 -> 2.9016
A41: 45562 | B41: Friday | C41: 0.9194 | D41: N | G41: 558 | H41: =G41-(C41*G41) -> 44.9748 | I41: =H41*$H$5 -> 2473.614 | J41: =G41-(G41*J$3) -> 27.9 | K41: =J41-H41 -> -17.0748
...

Sheet Sheldon Elementary
H1: =SUM(H7:H215) -> -331.8503
A2: SHELDON ELEMENTARY | E2: Estimated $ Missed Annually | G2: District Goal | H2: Campus Teams HIGHLIGHTED CELLS INDICATE # OF STUDENTS ABSENT ABOVE DISTRICT GOAL
E3: =SUM(F7:F128) -> 158482.73 | G3: 0.95
E4: Estimated $ Per Student
E5: 55
A6: Date | B6: Day of the Week | C6: Campus ADA % | D6: Enrollment | E6: # Students Absent | F6: Estimated $ Missed | G6: DISTRICTS # ABS GOAL | H6: # OF STUDENTS ABSENT
A7: 45516 | B7: Monday | C7: 1 | D7: 558 | E7: =D7-(C7*D7) -> 0 | F7: =E7*$E$5 -> 0 | G7: 0 | H7: =G7-E7 -> 0
A8: 45517 | B8: Tuesday | C8: 0.9878 | D8: 572 | E8: =D8-(C8*D8) -> 6.9784 | F8: =E8*$E$5 -> 383.812 | G8: =D8-(D8*G$3) -> 28.6 | H8: =G8-E8 -> 21.6216
A9: 45518 | B9: Wednesday | C9: 0.9757 | D9: 577 | E9: =D9-(C9*D9) -> 14.0211 | F9: =E9*$E$5 -> 771.1605 | G9: =D9-(D9*G$3) -> 28.85 | H9: =G9-E9 -> 14.8289
A10: 45519 | B10: Thursday | C10: 0.9743 | D10: 583 | E10: =D10-(C10*D10) -> 14.9831 | F10: =E10*$E$5 -> 824.0705 | G10: =D10-(D10*G$3) -> 29.15 | H10: =G10-E10 -> 14.1669
A11: 45520 | B11: Friday | C11: 0.976 | D11: 583 | E11: =D11-(C11*D11) -> 13.992 | F11: =E11*$E$5 -> 769.56 | G11: =D11-(D11*G$3) -> 29.15 | H11: =G11-E11 -> 15.158
A12: 45523 | B12: Monday | C12: 0.9591 | D12: 587 | E12: =D12-(C12*D12) -> 24.0083 | F12: =E12*$E$5 -> 1320.4565 | G12: =D12-(D12*G$3) -> 29.35 | H12: =G12-E12 -> 5.3417
A13: 45524 | B13: Tuesday | C13: 0.9474 | D13: 589 | E13: =D13-(C13*D13) -> 30.9814 | F13: =E13*$E$5 -> 1703.977 | G13: =D13-(D13*G$3) -> 29.45 | H13: =G13-E13 -> -1.5314
A14: 45525 | B14: Wednesday | C14: 0.9492 | D14: 591 | E14: =D14-(C14*D14) -> 30.0228 | F14: =E14*$E$5 -> 1651.254 | G14: =D14-(D14*G$3) -> 29.55 | H14: =G14-E14 -> -0.4728
A15: 45526 | B15: Thursday | C15: 0.9713 | D15: 592 | E15: =D15-(C15*D15) -> 16.9904 | F15: =E15*$E$5 -> 934.472 | G15: =D15-(D15*G$3) -> 29.6 | H15: =G15-E15 -> 12.6096
A16: 45527 | B16: Friday | C16: 0.9356 | D16: 590 | E16: =D16-(C16*D16) -> 37.996 | F16: =E16*$E$5 -> 2089.78 | G16: =D16-(D16*G$3) -> 29.5 | H16: =G16-E16 -> -8.496
A17: 45530 | B17: Monday | C17: 0.939 | D17: 590 | E17: =D17-(C17*D17) -> 35.99 | F17: =E17*$E$5 -> 1979.45 | G17: =D17-(D17*G$3) -> 29.5 | H17: =G17-E17 -> -6.49
A18: 45531 | B18: Tuesday | C18: 0.9595 | D18: 593 | E18: =D18-(C18*D18) -> 24.0165 | F18: =E18*$E$5 -> 1320.9075 | G18: =D18-(D18*G$3) -> 29.65 | H18: =G18-E18 -> 5.6335
A19: 45532 | B19: Wednesday | C19: 0.9612 | D19: 593 | E19: =D19-(C19*D19) -> 23.0084 | F19: =E19*$E$5 -> 1265.462 | G19: =D19-(D19*G$3) -> 29.65 | H19: =G19-E19 -> 6.6416
... A21: 45534 | B21: Friday | C21: 0.9359 | D21: 593 | E21: =D21-(C21*D21) -> 38.0113 | F21: =E21*$E$5 -> 2090.6215 | G21: =D21-(D21*G$3) -> 29.65 | H21: =G21-E21 -> -8.3613
A22: 45537 | B22: Monday | E22: =D22-(C22*D22) -> 0 | F22: =E22*$E$5 -> 0 | G22: =D22-(D22*G$3) -> 0 | H22: =G22-E22 -> 0
A23: 45538 | B23: Tuesday | C23: 0.9327 | D23: 594 | E23: =D23-(C23*D23) -> 39.9762 | F23: =E23*$E$5 -> 2198.691 | G23: =D23-(D23*G$3) -> 29.7 | H23: =G23-E23 -> -10.2762
A24: 45539 | B24: Wednesday | C24: 0.9613 | D24: 595 | E24: =D24-(C24*D24) -> 23.0265 | F24: =E24*$E$5 -> 1266.4575 | G24: =D24-(D24*G$3) -> 29.75 | H24: =G24-E24 -> 6.7235
A25: 45540 | B25: Thursday | C25: 0.9562 | D25: 594 | E25: =D25-(C25*D25) -> 26.0172 | F25: =E25*$E$5 -> 1430.946 | G25: =D25-(D25*G$3) -> 29.7 | H25: =G25-E25 -> 3.6828
A26: 45541 | B26: Friday | C26: 0.9528 | D26: 593 | E26: =D26-(C26*D26) -> 27.9896 | F26: =E26*$E$5 -> 1539.428 | G26: =D26-(D26*G$3) -> 29.65 | H26: =G26-E26 -> 1.6604
A27: 45544 | B27: Monday | C27: 0.9695 | D27: 591 | E27: =D27-(C27*D27) -> 18.0255 | F27: =E27*$E$5 -> 991.4025 | G27: =D27-(D27*G$3) -> 29.55 | H27: =G27-E27 -> 11.5245
A28: 45545 | B28: Tuesday | C28: 0.9542 | D28: 590 | E28: =D28-(C28*D28) -> 27.022 | F28: =E28*$E$5 -> 1486.21 | G28: =D28-(D28*G$3) -> 29.5 | H28: =G28-E28 -> 2.478
A29: 45546 | B29: Wednesday | C29: 0.9492 | D29: 590 | E29: =D29-(C29*D29) -> 29.972 | F29: =E29*$E$5 -> 1648.46 | G29: =D29-(D29*G$3) -> 29.5 | H29: =G29-E29 -> -0.472
A30: 45547 | B30: Thursday | C30: 0.9644 | D30: 590 | E30: =D30-(C30*D30) -> 21.004 | F30: =E30*$E$5 -> 1155.22 | G30: =D30-(D30*G$3) -> 29.5 | H30: =G30-E30 -> 8.496
A31: 45548 | B31: Friday | C31: 0.9475 | D31: 590 | E31: =D31-(C31*D31) -> 30.975 | F31: =E31*$E$5 -> 1703.625 | G31: =D31-(D31*G$3) -> 29.5 | H31: =G31-E31 -> -1.475
A32: 45551 | B32: Monday | E32: =D32-(C32*D32) -> 0 | F32: =E32*$E$5 -> 0 | G32: =D32-(D32*G$3) -> 0 | H32: =G32-E32 -> 0
A33: 45552 | B33: Tuesday | C33: 0.961 | D33: 589 | E33: =D33-(C33*D33) -> 22.971 | F33: =E33*$E$5 -> 1263.405 | G33: =D33-(D33*G$3) -> 29.45 | H33: =G33-E33 -> 6.479
A34: 45553 | B34: Wednesday | C34: 0.9745 | D34: 589 | E34: =D34-(C34*D34) -> 15.0195 | F34: =E34*$E$5 -> 826.0725 | G34: =D34-(D34*G$3) -> 29.45 | H34: =G34-E34 -> 14.4305
A35: 45554 | B35: Thursday | C35: 0.9593 | D35: 589 | E35: =D35-(C35*D35) -> 23.9723 | F35: =E35*$E$5 -> 1318.4765 | G35: =D35-(D35*G$3) -> 29.45 | H35: =G35-E35 -> 5.4777
A36: 45555 | B36: Friday | C36: 0.944 | D36: 589 | E36: =D36-(C36*D36) -> 32.984 | F36: =E36*$E$5 -> 1814.12 | G36: =D36-(D36*G$3) -> 29.45 | H36: =G36-E36 -> -3.534
A37: 45558 | B37: Monday | C37: 0.9542 | D37: 590 | E37: =D37-(C37*D37) -> 27.022 | F37: =E37*$E$5 -> 1486.21 | G37: =D37-(D37*G$3) -> 29.5 | H37: =G37-E37 -> 2.478
A38: 45559 | B38: Tuesday | C38: 0.9695 | D38: 590 | E38: =D38-(C38*D38) -> 17.995 | F38: =E38*$E$5 -> 989.725 | G38: =D38-(D38*G$3) -> 29.5 | H38: =G38-E38 -> 11.505
A39: 45560 | B39: Wednesday | C39: 0.9662 | D39: 592 | E39: =D39-(C39*D39) -> 20.0096 | F39: =E39*$E$5 -> 1100.528 | G39: =D39-(D39*G$3) -> 29.6 | H39: =G39-E39 -> 9.5904
A40: 45561 | B40: Thursday | C40: 0.9764 | D40: 592 | E40: =D40-(C40*D40) -> 13.9712 | F40: =E40*$E$5 -> 768.416 | G40: =D40-(D40*G$3) -> 29.6 | H40: =G40-E40 -> 15.6288
A41: 45562 | B41: Friday | C41: 0.9459 | D41: 592 | E41: =D41-(C41*D41) -> 32.0272 | F41: =E41*$E$5 -> 1761.496 | G41: =D41-(D41*G$3) -> 29.6 | H41: =G41-E41 -> -2.4272
...

Sheet SLE
K1: =SUM(K10:K218) -> #REF!
H2: Estimated $ Missed Annually | J2: District Goal | K2: Campus Teams HIGHLIGHTED CELLS INDICATE # OF STUDENTS ABSENT ABOVE DISTRICT GOAL
H3: =SUM(I7:I128) -> 218997.97 | J3: 0.95
H4: Estimated $ Per Student
H5: 55
A6: Date | B6: Day of the Week | C6: Campus ADA % | D6: Is ADA Below 90%? (Yes/No) | E6: If "Yes" Give Reason | F6: Explain if "Other" | G6: Enrollment | H6: # Students Absent | I6: Estimated $ Missed | J6: DISTRICTS # ABS GOAL
A7: 45516 | B7: Monday | C7: 1 | D7: NO | G7: 585 | H7: =G7-(C7*G7) -> 0 | I7: =H7*$H$5 -> 0 | J7: 0 | K7: =J7-H7 -> 0
A8: 45517 | B8: Tuesday | C8: 0.9813 | D8: NO | G8: 591 | H8: =G8-(C8*G8) -> 11.0517 | I8: =H8*$H$5 -> 607.8435 | J8: 0 | K8: =J8-H8 -> -11.0517
A9: 45518 | B9: Wednesday | C9: 0.9832 | D9: NO | G9: 599 | H9: =G9-(C9*G9) -> 10.0632 | I9: =H9*$H$5 -> 553.476 | J9: 0 | K9: =J9-H9 -> -10.0632
A10: 45519 | B10: Thursday | C10: 0.985 | D10: NO | G10: 604 | H10: =G10-(C10*G10) -> 9.06 | I10: =H10*$H$5 -> 498.3 | J10: 0 | K10: =J10-H10 -> -9.06
A11: 45520 | B11: Friday | C11: 0.9785 | D11: NO | G11: 608 | H11: =G11-(C11*G11) -> 13.072 | I11: =H11*$H$5 -> 718.96 | J11: 0 | K11: =J11-H11 -> -13.072
A12: 45523 | B12: Monday | C12: 0.9446 | D12: NO | G12: 614 | H12: =G7-(C7*G7) -> 0 | I12: =H12*$H$5 -> 0 | J12: 0 | K12: =J12-H12 -> 0
A13: 45524 | B13: Tuesday | C13: 0.9642 | D13: NO | G13: 615 | H13: =G13-(C13*G13) -> 22.017 | I13: =H13*$H$5 -> 1210.935 | J13: 0 | K13: =J13-H13 -> -22.017
A14: 45525 | B14: Wednesday | C14: 0.9756 | D14: NO | G14: 616 | H14: =G14-(C14*G14) -> 15.0304 | I14: =H14*$H$5 -> 826.672 | J14: 0 | K14: =J14-H14 -> -15.0304
A15: 45526 | B15: Thursday | C15: 0.966 | D15: NO | G15: 618 | H15: =G15-(C15*G15) -> 21.012 | I15: =H15*$H$5 -> 1155.66 | J15: 0 | K15: =J15-H15 -> -21.012
A16: 45527 | B16: Friday | C16: 0.966 | D16: NO | G16: 619 | H16: =G16-(C16*G16) -> 21.046 | I16: =H16*$H$5 -> 1157.53 | J16: 0 | K16: =J16-H16 -> -21.046
A17: 45530 | B17: Monday | C17: 0.9515 | D17: NO | G17: 618 | H17: =G17-(C17*G17) -> 29.973 | I17: =H17*$H$5 -> 1648.515 | J17: 0 | K17: =J17-H17 -> -29.973
A18: 45531 | B18: Tuesday | C18: 0.9742 | D18: NO | G18: 619 | H18: =G18-(C18*G18) -> 15.9702 | I18: =H18*$H$5 -> 878.361 | J18: 0 | K18: =J18-H18 -> -15.9702
A19: 45532 | B19: Wednesday | C19: 0.9626 | D19: NO | G19: 620 | H19: =G19-(C19*G19) -> 23.188 | I19: =H19*$H$5 -> 1275.34 | J19: 0 | K19: =J19-H19 -> -23.188
A20: 45533 | B20: Thursday | C20: 0.9855 | D20: NO | G20: 620 | H20: =G20-(C20*G20) -> 8.99 | I20: =H20*$H$5 -> 494.45 | J20: 0 | K20: =J20-H20 -> -8.99
A21: 45534 | B21: Friday | C21: 0.9468 | D21: NO | G21: 620 | H21: =G21-(C21*G21) -> 32.984 | I21: =H21*$H$5 -> 1814.12 | J21: 0 | K21: =J21-H21 -> -32.984
A22: 45537 | B22: Monday | H22: =G22-(C22*G22) -> 0 | I22: =H22*$H$5 -> 0 | J22: 0 | K22: =J22-H22 -> 0
A23: 45538 | B23: Tuesday | C23: 0.9583 | D23: NO | G23: 624 | H23: =G23-(C23*G23) -> 26.0208 | I23: =H23*$H$5 -> 1431.144 | J23: 0 | K23: =J23-H23 -> -26.0208
A24: 45539 | B24: Wednesday | C24: 0.9711 | D24: NO | G24: 622 | H24: =G24-(C24*G24) -> 17.9758 | I24: =H24*$H$5 -> 988.669 | J24: 0 | K24: =J24-H24 -> -17.9758
A25: 45540 | B25: Thursday | C25: 0.9727 | D25: NO | G25: 622 | H25: =G25-(C25*G25) -> 16.9806 | I25: =H25*$H$5 -> 933.933 | J25: 0 | K25: =J25-H25 -> -16.9806
A26: 45541 | B26: Friday | C26: 0.9515 | D26: NO | G26: 622 | H26: =G26-(C26*G26) -> 30.167 | I26: =H26*$H$5 -> 1659.185 | J26: 0 | K26: =J26-H26 -> -30.167
A27: 45544 | B27: Monday | C27: 0.9583 | D27: NO | G27: 623 | H27: =G27-(C27*G27) -> 25.9791 | I27: =H27*$H$5 -> 1428.8505 | J27: 0 | K27: =J27-H27 -> -25.9791
A28: 45545 | B28: Tuesday | C28: 0.9585 | D28: NO | G28: 627 | H28: =G28-(C28*G28) -> 26.0205 | I28: =H28*$H$5 -> 1431.1275 | J28: 0 | K28: =J28-H28 -> -26.0205
A29: 45546 | B29: Wednesday | C29: 0.9522 | D29: NO | G29: 627 | H29: =G29-(C29*G29) -> 29.9706 | I29: =H29*$H$5 -> 1648.383 | J29: 0 | K29: =J29-H29 -> -29.9706
A30: 45547 | B30: Thursday | C30: 0.9617 | D30: NO | G30: 627 | H30: =G30-(C30*G30) -> 24.0141 | I30: =H30*$H$5 -> 1320.7755 | J30: 0 | K30: =J30-H30 -> -24.0141
A31: 45548 | B31: Friday | C31: 0.9601 | D31: NO | G31: 626 | H31: =G31-(C31*G31) -> 24.9774 | I31: =H31*$H$5 -> 1373.757 | J31: 0 | K31: =J31-H31 -> -24.9774
A32: 45551 | B32: Monday | H32: =G32-(C32*G32) -> 0 | I32: =H32*$H$5 -> 0 | J32: 0 | K32: =J32-H32 -> 0
A33: 45552 | B33: Tuesday | C33: 0.9571 | D33: NO | G33: 628 | H33: =G33-(C33*G33) -> 26.9412 | I33: =H33*$H$5 -> 1481.766 | J33: 0 | K33: =J33-H33 -> -26.9412
A34: 45553 | B34: Wednesday | C34: 0.9682 | D34: NO | G34: 628 | H34: =G34-(C34*G34) -> 19.9704 | I34: =H34*$H$5 -> 1098.372 | J34: 0 | K34: =J34-H34 -> -19.9704
A35: 45554 | B35: Thursday | C35: 0.9555 | D35: NO | G35: 628 | H35: =G35-(C35*G35) -> 27.946 | I35: =H35*$H$5 -> 1537.03 | J35: 0 | K35: =J35-H35 -> -27.946
A36: 45555 | B36: Friday | C36: 0.9475 | D36: NO | G36: 628 | H36: =G36-(C36*G36) -> 32.97 | I36: =H36*$H$5 -> 1813.35 | J36: 0 | K36: =J36-H36 -> -32.97
A37: 45558 | B37: Monday | C37: 0.9475 | D37: NO | G37: 629 | H37: =G37-(C37*G37) -> 33.0225 | I37: =H37*$H$5 -> 1816.2375 | J37: 0 | K37: =J37-H37 -> -33.0225
A38: 45559 | B38: Tuesday | C38: 0.9602 | D38: NO | G38: 628 | H38: =G38-(C38*G38) -> 24.9944 | I38: =H38*$H$5 -> 1374.692 | J38: 0 | K38: =J38-H38 -> -24.9944
A39: 45560 | B39: Wednesday | C39: 0.9745 | D39: NO | G39: 628 | H39: =G39-(C39*G39) -> 16.014 | I39: =H39*$H$5 -> 880.77 | J39: 0 | K39: =J39-H39 -> -16.014
A40: 45561 | B40: Thursday | C40: 0.9666 | D40: NO | G40: 628 | H40: =G40-(C40*G40) -> 20.9752 | I40: =H40*$H$5 -> 1153.636 | J40: 0 | K40: =J40-H40 -> -20.9752
...

Sheet GE
K1: =SUM(K7:K215) -> #REF!
H2: Estimated $ Missed Annually | J2: District Goal | K2: Campus Teams HIGHLIGHTED CELLS INDICATE # OF STUDENTS ABSENT ABOVE DISTRICT GOAL
H3: =SUM(I7:I128) -> 165234.25 | J3: 0.95
H4: Estimated $ Per Student
H5: 55
H6: # Students Absent | I6: Estimated $ Missed | J6: DISTRICTS # ABS GOAL
A7: 45516 | B7: Monday | C7: 1 | D7: N | G7: 549 | H7: =G7-(C7*G7) -> 0 | I7: =H7*$H$5 -> 0 | J7: 0 | K7: =J7-H7 -> 0
A8: 45517 | B8: Tuesday | C8: 0.9965 | D8: N | G8: 571 | H8: =G8-(C8*G8) -> 1.9985 | I8: =H8*$H$5 -> 109.9175 | J8: =G8-(G8*J$3) -> 28.55 | K8: =J8-H8 -> 26.5515
A9: 45518 | B9: Wednesday | C9: 0.9826 | D9: N | G9: 575 | H9: =G9-(C9*G9) -> 10.005 | I9: =H9*$H$5 -> 550.275 | J9: =G9-(G9*J$3) -> 28.75 | K9: =J9-H9 -> 18.745
A10: 45519 | B10: Thursday | C10: 0.9861 | D10: N | G10: 576 | H10: =G10-(C10*G10) -> 8.0064 | I10: =H10*$H$5 -> 440.352 | J10: =G10-(G10*J$3) -> 28.8 | K10: =J10-H10 -> 20.7936
A11: 45520 | B11: Friday | C11: 0.9587 | D11: N | G11: 581 | H11: =G11-(C11*G11) -> 23.9953 | I11: =H11*$H$5 -> 1319.7415 | J11: =G11-(G11*J$3) -> 29.05 | K11: =J11-H11 -> 5.0547
A12: 45523 | B12: Monday | C12: 0.9464 | D12: N | E12: Health | G12: 597 | H12: =G12-(C12*G12) -> 31.9992 | I12: =H12*$H$5 -> 1759.956 | J12: =G12-(G12*J$3) -> 29.85 | K12: =J12-H12 -> -2.1492
A13: 45524 | B13: Tuesday | C13: 0.975 | D13: N | G13: 599 | H13: =G13-(C13*G13) -> 14.975 | I13: =H13*$H$5 -> 823.625 | J13: =G13-(G13*J$3) -> 29.95 | K13: =J13-H13 -> 14.975
A14: 45525 | B14: Wednesday | C14: 0.9635 | D14: N | G14: 603 | H14: =G14-(C14*G14) -> 22.0095 | I14: =H14*$H$5 -> 1210.5225 | J14: =G14-(G14*J$3) -> 30.15 | K14: =J14-H14 -> 8.1405
A15: 45526 | B15: Thursday | C15: 0.9635 | D15: N | G15: 603 | H15: =G15-(C15*G15) -> 22.0095 | I15: =H15*$H$5 -> 1210.5225 | J15: =G15-(G15*J$3) -> 30.15 | K15: =J15-H15 -> 8.1405
A16: 45527 | B16: Friday | C16: 0.932 | D16: N | G16: 603 | H16: =G16-(C16*G16) -> 41.004 | I16: =H16*$H$5 -> 2255.22 | J16: =G16-(G16*J$3) -> 30.15 | K16: =J16-H16 -> -10.854
A17: 45530 | B17: Monday | C17: 0.9536 | D17: N | G17: 603 | H17: =G17-(C17*G17) -> 27.9792 | I17: =H17*$H$5 -> 1538.856 | J17: =G17-(G17*J$3) -> 30.15 | K17: =J17-H17 -> 2.1708
A18: 45531 | B18: Tuesday | C18: 0.9586 | D18: N | G18: 604 | H18: =G18-(C18*G18) -> 25.0056 | I18: =H18*$H$5 -> 1375.308 | J18: =G18-(G18*J$3) -> 30.2 | K18: =J18-H18 -> 5.1944
A19: 45532 | B19: Wednesday | C19: 0.9404 | D19: N | G19: 604 | H19: =G19-(C19*G19) -> 35.9984 | I19: =H19*$H$5 -> 1979.912 | J19: =G19-(G19*J$3) -> 30.2 | K19: =J19-H19 -> -5.7984
A20: 45533 | B20: Thursday | C20: 0.9553 | D20: N | G20: 604 | H20: =G20-(C20*G20) -> 26.9988 | I20: =H20*$H$5 -> 1484.934 | J20: =G20-(G20*J$3) -> 30.2 | K20: =J20-H20 -> 3.2012
A21: 45534 | B21: Friday | C21: 0.9272 | D21: N | G21: 604 | H21: =G21-(C21*G21) -> 43.9712 | I21: =H21*$H$5 -> 2418.416 | J21: =G21-(G21*J$3) -> 30.2 | K21: =J21-H21 -> -13.7712
A22: 45537 | B22: Monday | H22: =G22-(C22*G22) -> 0 | I22: =H22*$H$5 -> 0 | J22: =G22-(G22*J$3) -> 0 | K22: =J22-H22 -> 0
A23: 45538 | B23: Tuesday | C23: 0.9423 | D23: N | G23: 607 | H23: =G23-(C23*G23) -> 35.0239 | I23: =H23*$H$5 -> 1926.3145 | J23: =G23-(G23*J$3) -> 30.35 | K23: =J23-H23 -> -4.6739
A24: 45539 | B24: Wednesday | C24: 0.9555 | D24: N | G24: 607 | H24: =G24-(C24*G24) -> 27.0115 | I24: =H24*$H$5 -> 1485.6325 | J24: =G24-(G24*J$3) -> 30.35 | K24: =J24-H24 -> 3.3385
A25: 45540 | B25: Thursday | C25: 0.9539 | D25: N | G25: 608 | H25: =G25-(C26*G25) -> 37.0272 | I25: =H25*$H$5 -> 2036.496 | J25: =G25-(G25*J$3) -> 30.4 | K25: =J25-H25 -> -6.6272
A26: 45541 | B26: Friday | C26: 0.9391 | D26: N | G26: 608 | H26: =G26-(C27*G26) -> 37.0272 | I26: =H26*$H$5 -> 2036.496 | J26: =G26-(G26*J$3) -> 30.4 | K26: =J26-H26 -> -6.6272
A27: 45544 | B27: Monday | C27: 0.9391 | D27: N | G27: 608 | H27: =G27-(C28*G27) -> 22.9824 | I27: =H27*$H$5 -> 1264.032 | J27: =G27-(G27*J$3) -> 30.4 | K27: =J27-H27 -> 7.4176
A28: 45545 | B28: Tuesday | C28: 0.9622 | D28: N | G28: 607 | H28: =G28-(C29*G28) -> 26.8901 | I28: =H28*$H$5 -> 1478.9555 | J28: =G28-(G28*J$3) -> 30.35 | K28: =J28-H28 -> 3.4599
A29: 45546 | B29: Wednesday | C29: 0.9557 | D29: N | G29: 609 | H29: =G29-(C29*G29) -> 26.9787 | I29: =H29*$H$5 -> 1483.8285 | J29: =G29-(G29*J$3) -> 30.45 | K29: =J29-H29 -> 3.4713
A30: 45547 | B30: Thursday | C30: 0.9541 | D30: N | G30: 610 | H30: =G30-(C30*G30) -> 27.999 | I30: =H30*$H$5 -> 1539.945 | J30: =G30-(G30*J$3) -> 30.5 | K30: =J30-H30 -> 2.501
A31: 45548 | B31: Friday | C31: 0.9475 | D31: N | G31: 610 | H31: =G31-(C31*G31) -> 32.025 | I31: =H31*$H$5 -> 1761.375 | J31: =G31-(G31*J$3) -> 30.5 | K31: =J31-H31 -> -1.525
A32: 45551 | B32: Monday | H32: =G32-(C32*G32) -> 0 | I32: =H32*$H$5 -> 0 | J32: =G32-(G32*J$3) -> 0 | K32: =J32-H32 -> 0
A33: 45552 | B33: Tuesday | C33: 0.9671 | D33: N | G33: 607 | H33: =G33-(C33*G33) -> 19.9703 | I33: =H33*$H$5 -> 1098.3665 | J33: =G33-(G33*J$3) -> 30.35 | K33: =J33-H33 -> 10.3797
A34: 45553 | B34: Wednesday | C34: 0.9638 | D34: N | G34: 607 | H34: =G34-(C34*G34) -> 21.9734 | I34: =H34*$H$5 -> 1208.537 | J34: =G34-(G34*J$3) -> 30.35 | K34: =J34-H34 -> 8.3766
A35: 45554 | B35: Thursday | C35: 0.9555 | D35: N | G35: 607 | H35: =G35-(C35*G35) -> 27.0115 | I35: =H35*$H$5 -> 1485.6325 | J35: =G35-(G35*J$3) -> 30.35 | K35: =J35-H35 -> 3.3385
A36: 45555 | B36: Friday | C36: 0.8896 | D36: N | G36: 606 | H36: =G36-(C36*G36) -> 66.9024 | I36: =H36*$H$5 -> 3679.632 | J36: =G36-(G36*J$3) -> 30.3 | K36: =J36-H36 -> -36.6024
