Workbook

Sheet 2024-25 DIBELS MOY
A1: Student Name | B1: Local ID | C1: Current Campus | D1: Grade | E1: Subject | F1: Special Ed Indicator | G1: Economic Disadvantage | H1: Emergent Bilingual | I1: Ethnicity | K1: Test Lang | L1: Instructor | M1: Instructor ID | N1: 2024 STAAR | O1: STAAR Per Lev | P1: DCA#2 | Q1: DCA#2 Per Lev | R1: Delta | S1: Growth | T1: HB 1416 | U1: HB 1416 Delta | V1: Total Growth DCA#2 | W1: App | X1: Meets | Y1: Masters | Z1: CS | AA1: DCA 2 vs DCA 1 | AB1: DCA#1 | AC1: DCA#1 Per Lev | AD1: Delta | AE1: Growth | AF1: HB 1416 | AG1: HB 1616 Delta | AH1: Total Growth DCA 1 | AI1: App | AJ1: Meets | AK1: Masters | AL1: CS
A2: ADELAJA, ANNA | B2: =VLOOKUP(A2,'[1]2025 KG Students'!$C$2:$D$630,2,FALSE) -> 85060 | C2: SHELDON EARLY CHILDHOOD ACADEMY | D2: K | E2: RLA | F2: No | G2: No | I2: B | J2: N | K2: English | L2: LUMPFORD, JOYLANN | M2: =VLOOKUP(L2,'[2]2025 Teachers (1)'!$C$2:$D$807,2,FALSE) -> 18548 | P2: 0.55 | AH2: =VLOOKUP(A2,'2024-25 DIBELS BOY '!A2:AP372,42,FALSE) -> 0.46833333
A3: AGUILAR, AGUSTIN | B3: =VLOOKUP(A3,'[1]2025 KG Students'!$C$2:$D$630,2,FALSE) -> 85230 | C3: SHELDON EARLY CHILDHOOD ACADEMY | D3: K | E3: RLA | F3: No | G3: No | I3: M | J3: Y | K3: English | L3: LEZAMA, MARIA | M3: =VLOOKUP(L3,'[2]2025 Teachers (1)'!$C$2:$D$807,2,FALSE) -> 13866 | P3: 0.625 | AH3: =VLOOKUP(A3,'2024-25 DIBELS BOY '!A3:AP373,42,FALSE) -> 0.49
A4: AGUILAR, ARIANA | B4: =VLOOKUP(A4,'[1]2025 KG Students'!$C$2:$D$630,2,FALSE) -> 87397 | C4: SHELDON EARLY CHILDHOOD ACADEMY | D4: K | E4: RLA | F4: No | G4: No | I4: M | J4: Y | K4: English | L4: MCDONALD, TAVIA | M4: =VLOOKUP(L4,'[2]2025 Teachers (1)'!$C$2:$D$807,2,FALSE) -> 18050 | P4: 0.665 | AH4: =VLOOKUP(A4,'2024-25 DIBELS BOY '!A4:AP374,42,FALSE) -> 0.65
A5: ALEXANDER, RANIYAH | B5: =VLOOKUP(A5,'[1]2025 KG Students'!$C$2:$D$630,2,FALSE) -> 85215 | C5: SHELDON EARLY CHILDHOOD ACADEMY | D5: K | E5: RLA | F5: No | G5: No | I5: B | J5: N | K5: English | L5: MCDONALD, TAVIA | M5: =VLOOKUP(L5,'[2]2025 Teachers (1)'!$C$2:$D$807,2,FALSE) -> 18050 | P5: 0.61666667 | AH5: =VLOOKUP(A5,'2024-25 DIBELS BOY '!A5:AP375,42,FALSE) -> 0.555
A6: ALLEN, KAYCEN | B6: =VLOOKUP(A6,'[1]2025 KG Students'!$C$2:$D$630,2,FALSE) -> 87566 | C6: SHELDON EARLY CHILDHOOD ACADEMY | D6: K | E6: RLA | F6: No | G6: No | I6: B | J6: N | K6: English | L6: MCDONALD, TAVIA | M6: =VLOOKUP(L6,'[2]2025 Teachers (1)'!$C$2:$D$807,2,FALSE) -> 18050 | P6: 0.53333333 | AH6: =VLOOKUP(A6,'2024-25 DIBELS BOY '!A6:AP376,42,FALSE) -> 0.44
A7: ALVARADO, LUNA | B7: =VLOOKUP(A7,'[1]2025 KG Students'!$C$2:$D$630,2,FALSE) -> 85437 | C7: SHELDON EARLY CHILDHOOD ACADEMY | D7: K | E7: RLA | F7: No | G7: No | I7: M | J7: Y | K7: English | L7: GAINES, IDA | M7: =VLOOKUP(L7,'[2]2025 Teachers (1)'!$C$2:$D$807,2,FALSE) -> 15019 | P7: 0.565 | AH7: =VLOOKUP(A7,'2024-25 DIBELS BOY '!A7:AP377,42,FALSE) -> 0.44833333
A8: ANCIRA, XANTINO | B8: =VLOOKUP(A8,'[1]2025 KG Students'!$C$2:$D$630,2,FALSE) -> 88055 | C8: SHELDON EARLY CHILDHOOD ACADEMY | D8: K | E8: RLA | F8: No | G8: No | I8: M | J8: Y | K8: English | L8: JENKINS, SARAH | M8: =VLOOKUP(L8,'[2]2025 Teachers (1)'!$C$2:$D$807,2,FALSE) -> 18825 | P8: 0.60666667 | AH8: =VLOOKUP(A8,'2024-25 DIBELS BOY '!A8:AP378,42,FALSE) -> 0.51
A9: ARZU, JAHMIERE | B9: =VLOOKUP(A9,'[1]2025 KG Students'!$C$2:$D$630,2,FALSE) -> 85672 | C9: SHELDON EARLY CHILDHOOD ACADEMY | D9: K | E9: RLA | F9: No | G9: No | I9: B | J9: N | K9: English | L9: NED-WILLIAMS, JASMINE | M9: =VLOOKUP(L9,'[2]2025 Teachers (1)'!$C$2:$D$807,2,FALSE) -> 17879 | P9: 0.655 | AH9: =VLOOKUP(A9,'2024-25 DIBELS BOY '!A9:AP379,42,FALSE) -> 0.46666667
A10: ASCENCIO, FRANCISCO | B10: =VLOOKUP(A10,'[1]2025 KG Students'!$C$2:$D$630,2,FALSE) -> 85057 | C10: SHELDON EARLY CHILDHOOD ACADEMY | D10: K | E10: RLA | F10: No | G10: No | I10: M | J10: Y | K10: English | L10: CASTILLO-LOPEZ, JOANA | M10: =VLOOKUP(L10,'[2]2025 Teachers (1)'!$C$2:$D$807,2,FALSE) -> 14530 | P10: 0.60666667 | AH10: =VLOOKUP(A10,'2024-25 DIBELS BOY '!A10:AP380,42,FALSE) -> 0.47666667
A11: AVELLANEDA, DALYLAH | B11: =VLOOKUP(A11,'[1]2025 KG Students'!$C$2:$D$630,2,FALSE) -> 85476 | C11: SHELDON EARLY CHILDHOOD ACADEMY | D11: K | E11: RLA | F11: No | G11: No | I11: M | J11: Y | K11: English | L11: CATAPANO, APRIL | M11: =VLOOKUP(L11,'[2]2025 Teachers (1)'!$C$2:$D$807,2,FALSE) -> 17649 | P11: 0.63666667 | AH11: =VLOOKUP(A11,'2024-25 DIBELS BOY '!A11:AP381,42,FALSE) -> 0.54333333
A12: BAILEY, EZRA | B12: =VLOOKUP(A12,'[1]2025 KG Students'!$C$2:$D$630,2,FALSE) -> 87591 | C12: SHELDON EARLY CHILDHOOD ACADEMY | D12: K | E12: RLA | F12: No | G12: No | I12: M | J12: Y | K12: English | L12: CATAPANO, APRIL | M12: =VLOOKUP(L12,'[2]2025 Teachers (1)'!$C$2:$D$807,2,FALSE) -> 17649 | P12: 0.62333333 | AH12: =VLOOKUP(A12,'2024-25 DIBELS BOY '!A12:AP382,42,FALSE) -> 0.555
A13: BARBOSA, EMMANUEL | B13: =VLOOKUP(A13,'[1]2025 KG Students'!$C$2:$D$630,2,FALSE) -> 87458 | C13: SHELDON EARLY CHILDHOOD ACADEMY | D13: K | E13: RLA | F13: No | G13: No | I13: M | J13: Y | K13: English | L13: CATAPANO, APRIL | M13: =VLOOKUP(L13,'[2]2025 Teachers (1)'!$C$2:$D$807,2,FALSE) -> 17649 | P13: 0.62333333 | AH13: =VLOOKUP(A13,'2024-25 DIBELS BOY '!A13:AP383,42,FALSE) -> 0.41333333
... A347: TREVINO, DALEYZA | B347: =VLOOKUP(A347,'[1]2025 KG Students'!$C$2:$D$630,2,FALSE) -> 85574 | C347: STEPHANIE CRAVENS EARLY CHILDHOOD | D347: K | E347: RLA | F347: No | G347: No | I347: M | J347: Y | K347: English | L347: JOHNSON, LATOYA | M347: =VLOOKUP(L347,'[2]2025 Teachers (1)'!$C$2:$D$807,2,FALSE) -> 10374 | P347: 0.55666667 | AH347: =VLOOKUP(A347,'2024-25 DIBELS BOY '!A347:AP717,42,FALSE) -> 0.44166667
A348: UMANA, ALESSANDRA | B348: =VLOOKUP(A348,'[1]2025 KG Students'!$C$2:$D$630,2,FALSE) -> 85170 | C348: STEPHANIE CRAVENS EARLY CHILDHOOD | D348: K | E348: RLA | F348: No | G348: No | I348: M | J348: Y | K348: English | L348: CUNNINGHAM, MELISSA | M348: 18548 | P348: 0.675 | AH348: =VLOOKUP(A348,'2024-25 DIBELS BOY '!A348:AP718,42,FALSE) -> 0.55833333
A349: UMANA, CATALINA | B349: =VLOOKUP(A349,'[1]2025 KG Students'!$C$2:$D$630,2,FALSE) -> 86084 | C349: STEPHANIE CRAVENS EARLY CHILDHOOD | D349: K | E349: RLA | F349: No | G349: No | I349: M | J349: Y | K349: English | L349: CUNNINGHAM, MELISSA | M349: 13866 | P349: 0.58166667 | AH349: =VLOOKUP(A349,'2024-25 DIBELS BOY '!A349:AP719,42,FALSE) -> 0.41833333
A350: VALDEZ, EMILIO | B350: =VLOOKUP(A350,'[1]2025 KG Students'!$C$2:$D$630,2,FALSE) -> 87306 | C350: STEPHANIE CRAVENS EARLY CHILDHOOD | D350: K | E350: RLA | F350: No | G350: No | I350: M | J350: Y | K350: English | L350: DELEON, MARIA | M350: 18050 | P350: 0.65333333 | AH350: =VLOOKUP(A350,'2024-25 DIBELS BOY '!A350:AP720,42,FALSE) -> 0.445
A351: VALLES, MAYRA | B351: =VLOOKUP(A351,'[1]2025 KG Students'!$C$2:$D$630,2,FALSE) -> 88863 | C351: STEPHANIE CRAVENS EARLY CHILDHOOD | D351: K | E351: RLA | F351: No | G351: No | I351: M | J351: Y | K351: English | L351: JOHNSON, LATOYA | M351: 18050 | P351: 0.53 | AH351: =VLOOKUP(A351,'2024-25 DIBELS BOY '!A351:AP721,42,FALSE) -> #N/A
A352: VASQUEZ, CATALINA | B352: =VLOOKUP(A352,'[1]2025 KG Students'!$C$2:$D$630,2,FALSE) -> 86004 | C352: STEPHANIE CRAVENS EARLY CHILDHOOD | D352: K | E352: RLA | F352: No | G352: No | I352: M | J352: Y | K352: English | L352: CUSSEN, KATHIE | M352: 18050 | P352: 0.63333333 | AH352: =VLOOKUP(A352,'2024-25 DIBELS BOY '!A352:AP722,42,FALSE) -> 0.48666667
A353: VASQUEZ, HANNAH | B353: =VLOOKUP(A353,'[1]2025 KG Students'!$C$2:$D$630,2,FALSE) -> 85153 | C353: STEPHANIE CRAVENS EARLY CHILDHOOD | D353: K | E353: RLA | F353: No | G353: No | I353: M | J353: Y | K353: English | L353: CONNELL, KATLIN | M353: 18050 | P353: 0.64833333 | AH353: =VLOOKUP(A353,'2024-25 DIBELS BOY '!A353:AP723,42,FALSE) -> 0.55666667
A354: VELAZQUEZ, JIONNI | B354: =VLOOKUP(A354,'[1]2025 KG Students'!$C$2:$D$630,2,FALSE) -> 85162 | C354: STEPHANIE CRAVENS EARLY CHILDHOOD | D354: K | E354: RLA | F354: No | G354: No | I354: M | J354: Y | K354: English | L354: PAYNE, SAMANTHA | P354: 0.75333333 | AH354: =VLOOKUP(A354,'2024-25 DIBELS BOY '!A354:AP724,42,FALSE) -> 0.55666667
A355: WALKER, TORI | B355: =VLOOKUP(A355,'[1]2025 KG Students'!$C$2:$D$630,2,FALSE) -> 86219 | C355: STEPHANIE CRAVENS EARLY CHILDHOOD | D355: K | E355: RLA | F355: No | G355: No | I355: B | J355: N | K355: English | L355: CONNELL, KATLIN | M355: 15019 | P355: 0.635 | AH355: =VLOOKUP(A355,'2024-25 DIBELS BOY '!A355:AP725,42,FALSE) -> 0.49833333
A356: WALKER-AMORA-TRUSCOTT, NAYELI | B356: =VLOOKUP(A356,'[1]2025 KG Students'!$C$2:$D$630,2,FALSE) -> 86020 | C356: STEPHANIE CRAVENS EARLY CHILDHOOD | D356: K | E356: RLA | F356: No | G356: No | I356: M | J356: Y | K356: English | L356: CUNNINGHAM, MELISSA | M356: 18825 | P356: 0.67333333 | AH356: =VLOOKUP(A356,'2024-25 DIBELS BOY '!A356:AP726,42,FALSE) -> 0.605
A357: WEBB, CATALEYA | B357: =VLOOKUP(A357,'[1]2025 KG Students'!$C$2:$D$630,2,FALSE) -> 85702 | C357: STEPHANIE CRAVENS EARLY CHILDHOOD | D357: K | E357: RLA | F357: No | G357: No | I357: B | J357: N | K357: English | L357: FEEMSTER, AVERY | M357: 17879 | P357: 0.65833333 | AH357: =VLOOKUP(A357,'2024-25 DIBELS BOY '!A357:AP727,42,FALSE) -> 0.5
A358: WILLIAMS, CARTER | B358: =VLOOKUP(A358,'[1]2025 KG Students'!$C$2:$D$630,2,FALSE) -> 85614 | C358: STEPHANIE CRAVENS EARLY CHILDHOOD | D358: K | E358: RLA | F358: No | G358: No | I358: M | J358: Y | K358: English | L358: CUNNINGHAM, MELISSA | M358: 14530 | P358: 0.71166667 | AH358: =VLOOKUP(A358,'2024-25 DIBELS BOY '!A358:AP728,42,FALSE) -> 0.60333333
A359: WILLIAMS, GIANNIS | B359: =VLOOKUP(A359,'[1]2025 KG Students'!$C$2:$D$630,2,FALSE) -> 85576 | C359: STEPHANIE CRAVENS EARLY CHILDHOOD | D359: K | E359: RLA | F359: No | G359: No | I359: B | J359: N | K359: English | L359: GALLARDO, SAVANNAH | M359: 17649 | P359: 0.645 | AH359: =VLOOKUP(A359,'2024-25 DIBELS BOY '!A359:AP729,42,FALSE) -> 0.525
A360: WILLIAMS, KARTER | B360: =VLOOKUP(A360,'[1]2025 KG Students'!$C$2:$D$630,2,FALSE) -> 86400 | C360: STEPHANIE CRAVENS EARLY CHILDHOOD | D360: K | E360: RLA | F360: No | G360: No | I360: B | J360: N | K360: English | L360: GALLARDO, SAVANNAH | M360: 17649 | P360: 0.585 | AH360: =VLOOKUP(A360,'2024-25 DIBELS BOY '!A360:AP730,42,FALSE) -> 0.5
A361: WILLIAMS, MA'LANEI | B361: =VLOOKUP(A361,'[1]2025 KG Students'!$C$2:$D$630,2,FALSE) -> 85771 | C361: STEPHANIE CRAVENS EARLY CHILDHOOD | D361: K | E361: RLA | F361: No | G361: No | I361: B | J361: N | K361: English | L361: CUSSEN, KATHIE | M361: 17649 | P361: 0.56166667 | AH361: =VLOOKUP(A361,'2024-25 DIBELS BOY '!A361:AP731,42,FALSE) -> 0.46833333
A362: WILLIAMS, ZIYA | B362: =VLOOKUP(A362,'[1]2025 KG Students'!$C$2:$D$630,2,FALSE) -> 85523 | C362: STEPHANIE CRAVENS EARLY CHILDHOOD | D362: K | E362: RLA | F362: No | G362: No | I362: B | J362: N | K362: English | L362: GONZALEZ, CYNTHIA | M362: 18941 | P362: 0.65666667 | AH362: =VLOOKUP(A362,'2024-25 DIBELS BOY '!A362:AP732,42,FALSE) -> 0.58666667
A363: WILLIS, LAYLA | B363: =VLOOKUP(A363,'[1]2025 KG Students'!$C$2:$D$630,2,FALSE) -> 88418 | C363: STEPHANIE CRAVENS EARLY CHILDHOOD | D363: K | E363: RLA | F363: No | G363: No | I363: B | J363: N | K363: English | L363: GONZALEZ, CYNTHIA | M363: 18548 | P363: 0.56666667 | AH363: =VLOOKUP(A363,'2024-25 DIBELS BOY '!A363:AP733,42,FALSE) -> 0.43333333
A364: ZAPATA, ALBERT | B364: =VLOOKUP(A364,'[1]2025 KG Students'!$C$2:$D$630,2,FALSE) -> 88511 | C364: STEPHANIE CRAVENS EARLY CHILDHOOD | D364: K | E364: RLA | F364: No | G364: No | I364: W | J364: N | K364: English | L364: JOHNSON, LATOYA | M364: 17879 | P364: 0.53 | AH364: =VLOOKUP(A364,'2024-25 DIBELS BOY '!A364:AP734,42,FALSE) -> 0.41166667
A365: ZUNIGA, LEAH | B365: =VLOOKUP(A365,'[1]2025 KG Students'!$C$2:$D$630,2,FALSE) -> 87889 | C365: STEPHANIE CRAVENS EARLY CHILDHOOD | D365: K | E365: RLA | F365: No | G365: No | I365: M | J365: Y | K365: English | L365: CUNNINGHAM, MELISSA | M365: 13866 | P365: 0.66666667 | AH365: =VLOOKUP(A365,'2024-25 DIBELS BOY '!A365:AP735,42,FALSE) -> 0.66166667
B366: =VLOOKUP(A366,'[1]2025 KG Students'!$C$2:$D$630,2,FALSE) -> #N/A | D366: K | E366: RLA | F366: No | G366: No | I366: M | J366: Y | K366: English | P366: 0.66666667
M469: 18941
M470: 18941
M471: 18050
M472: 18050
M473: 17879
M474: 17879
M475: 15143
...

Sheet 2024-25 DIBELS BOY 
A1: Student Name | B1: Local ID | C1: Current Campus | D1: Grade | E1: Subject | F1: Special Ed Indicator | G1: Economic Disadvantage | H1: Emergent Bilingual | I1: Ethnicity | K1: Test Lang | L1: Instructor | M1: Instructor ID | N1: 2024 STAAR | O1: STAAR Per Lev | P1: DCA#2 | Q1: DCA#2 Per Lev | R1: Delta | S1: Growth | T1: HB 1416 | U1: HB 1416 Delta | V1: Total Growth DCA#2 | W1: App | X1: Meets | Y1: Masters | Z1: CS | AA1: DCA 2 vs DCA 1 | AB1: DCA#1 | AC1: DCA#1 Per Lev | AD1: Delta | AE1: Growth | AF1: HB 1416 | AG1: HB 1616 Delta | AH1: Total Growth DCA 1 | AI1: App | AJ1: Meets | AK1: Masters | AL1: CS | AM1: Benchmark Period | AN1: Composite Level | AO1: Composite Score | AP1: % Comp
A2: ADELAJA, ANNA | C2: SHELDON EARLY CHILDHOOD ACADEMY | D2: K | E2: RLA | F2: No | G2: No | I2: Race | J2: Hispanic or Latino Ethnicity | K2: English | L2: LUMPFORD, JOYLANN | AM2: BOY | AN2: Below Benchmark | AO2: 281 | AP2: 0.46833333
A3: AGUILAR, AGUSTIN | C3: SHELDON EARLY CHILDHOOD ACADEMY | D3: K | E3: RLA | F3: No | G3: No | I3: B | J3: N | K3: English | L3: LEZAMA, MARIA | AM3: BOY | AN3: Below Benchmark | AO3: 294 | AP3: 0.49
A4: AGUILAR, ARIANA | C4: SHELDON EARLY CHILDHOOD ACADEMY | D4: K | E4: RLA | F4: No | G4: No | I4: M | J4: Y | K4: English | L4: MCDONALD, TAVIA | AM4: BOY | AN4: Above Benchmark | AO4: 390 | AP4: 0.65
A5: ALEXANDER, RANIYAH | C5: SHELDON EARLY CHILDHOOD ACADEMY | D5: K | E5: RLA | F5: No | G5: No | I5: M | J5: Y | K5: English | L5: MCDONALD, TAVIA | AM5: BOY | AN5: Above Benchmark | AO5: 333 | AP5: 0.555
A6: ALEXANDER-YOUNG, PAISLEY | C6: SHELDON EARLY CHILDHOOD ACADEMY | D6: K | E6: RLA | F6: No | G6: No | I6: B | J6: N | K6: English | AM6: BOY | AN6: Below Benchmark | AO6: 297 | AP6: 0.495
A7: ALLEN, KAYCEN | C7: SHELDON EARLY CHILDHOOD ACADEMY | D7: K | E7: RLA | F7: No | G7: No | I7: B | J7: N | K7: English | L7: MCDONALD, TAVIA | AM7: BOY | AN7: Well Below Benchmark | AO7: 264 | AP7: 0.44
A8: ALVARADO, JOSHUA | C8: SHELDON EARLY CHILDHOOD ACADEMY | D8: K | E8: RLA | F8: No | G8: No | I8: B | J8: N | K8: English | AM8: BOY | AN8: At Benchmark | AO8: 310 | AP8: 0.51666667
A9: ALVARADO, LUNA | C9: SHELDON EARLY CHILDHOOD ACADEMY | D9: K | E9: RLA | F9: No | G9: No | I9: M | J9: Y | K9: English | L9: GAINES, IDA | AM9: BOY | AN9: Well Below Benchmark | AO9: 269 | AP9: 0.44833333
A10: ANCIRA, XANTINO | C10: SHELDON EARLY CHILDHOOD ACADEMY | D10: K | E10: RLA | F10: No | G10: No | I10: M | J10: Y | K10: English | L10: JENKINS, SARAH | AM10: BOY | AN10: At Benchmark | AO10: 306 | AP10: 0.51
A11: ANGULO, PRINCETON | C11: SHELDON EARLY CHILDHOOD ACADEMY | D11: K | E11: RLA | F11: No | G11: No | I11: M | J11: Y | K11: English | L11: JENKINS, SARAH | AM11: BOY | AN11: Below Benchmark | AO11: 289 | AP11: 0.48166667
A12: ARZU, JAHMIERE | C12: SHELDON EARLY CHILDHOOD ACADEMY | D12: K | E12: RLA | F12: No | G12: No | I12: M | J12: Y | K12: English | L12: NED-WILLIAMS, JASMINE | AM12: BOY | AN12: Below Benchmark | AO12: 280 | AP12: 0.46666667
A13: ASCENCIO, FRANCISCO | C13: SHELDON EARLY CHILDHOOD ACADEMY | D13: K | E13: RLA | F13: No | G13: No | I13: B | J13: N | K13: English | L13: CASTILLO-LOPEZ, JOANA | AM13: BOY | AN13: Below Benchmark | AO13: 286 | AP13: 0.47666667
A14: AVELLANEDA, DALYLAH | C14: SHELDON EARLY CHILDHOOD ACADEMY | D14: K | E14: RLA | F14: No | G14: No | I14: M | J14: Y | K14: English | L14: CATAPANO, APRIL | AM14: BOY | AN14: At Benchmark | AO14: 326 | AP14: 0.54333333
A15: BAILEY, EZRA | C15: SHELDON EARLY CHILDHOOD ACADEMY | D15: K | E15: RLA | F15: No | G15: No | I15: M | J15: Y | K15: English | L15: CATAPANO, APRIL | AM15: BOY | AN15: Above Benchmark | AO15: 333 | AP15: 0.555
A16: BARBOSA, EMMANUEL | C16: SHELDON EARLY CHILDHOOD ACADEMY | D16: K | E16: RLA | F16: No | G16: No | I16: M | J16: Y | K16: English | L16: CATAPANO, APRIL | AM16: BOY | AN16: Well Below Benchmark | AO16: 248 | AP16: 0.41333333
A17: BARNER, KAIDEN | C17: SHELDON EARLY CHILDHOOD ACADEMY | D17: K | E17: RLA | F17: No | G17: No | I17: M | J17: Y | K17: English | L17: TOLLEY, ANALISA | AM17: BOY | AN17: Above Benchmark | AO17: 433 | AP17: 0.72166667
A18: BASS, BLAKE | C18: SHELDON EARLY CHILDHOOD ACADEMY | D18: K | E18: RLA | F18: No | G18: No | I18: B | J18: N | K18: English | L18: LUMPFORD, JOYLANN | AM18: BOY | AN18: At Benchmark | AO18: 330 | AP18: 0.55
A19: BELEN, SOPHIA MAY | C19: SHELDON EARLY CHILDHOOD ACADEMY | D19: K | E19: RLA | F19: No | G19: No | I19: B | J19: N | K19: English | L19: CATAPANO, APRIL | AM19: BOY | AN19: Above Benchmark | AO19: 514 | AP19: 0.85666667
A20: BELLMORE, YULIANA | C20: SHELDON EARLY CHILDHOOD ACADEMY | D20: K | E20: RLA | F20: No | G20: No | I20: AS | J20: N | K20: English | L20: NED-WILLIAMS, JASMINE | AM20: BOY | AN20: Below Benchmark | AO20: 293 | AP20: 0.48833333
... A81: HILL, JEREMIAH | C81: SHELDON EARLY CHILDHOOD ACADEMY | D81: K | E81: RLA | F81: No | G81: No | I81: B | J81: N | K81: English | L81: ALLEN, NICKIE | AM81: BOY | AN81: Well Below Benchmark | AO81: 243 | AP81: 0.405
A82: HILL, QUEEN | C82: SHELDON EARLY CHILDHOOD ACADEMY | D82: K | E82: RLA | F82: No | G82: No | I82: M | J82: Y | K82: English | AM82: BOY | AN82: Well Below Benchmark | AO82: 254 | AP82: 0.42333333
A83: HINES, AMIER | C83: SHELDON EARLY CHILDHOOD ACADEMY | D83: K | E83: RLA | F83: No | G83: No | I83: M | J83: Y | K83: English | L83: NED-WILLIAMS, JASMINE | AM83: BOY | AN83: Above Benchmark | AO83: 387 | AP83: 0.645
A84: HUBBARD, SEBASTIAN | C84: SHELDON EARLY CHILDHOOD ACADEMY | D84: K | E84: RLA | F84: No | G84: No | I84: B | J84: N | K84: English | L84: JENKINS, SARAH | AM84: BOY | AN84: Above Benchmark | AO84: 339 | AP84: 0.565
A85: HYACINTH, DARIUS | C85: SHELDON EARLY CHILDHOOD ACADEMY | D85: K | E85: RLA | F85: No | G85: No | I85: B | J85: N | K85: English | L85: GAINES, IDA | AM85: BOY | AN85: At Benchmark | AO85: 313 | AP85: 0.52166667
A86: HYACINTH, NYA | C86: SHELDON EARLY CHILDHOOD ACADEMY | D86: K | E86: RLA | F86: No | G86: No | I86: B | J86: N | K86: English | L86: LEZAMA, MARIA | AM86: BOY | AN86: Well Below Benchmark | AO86: 262 | AP86: 0.43666667
A87: IVY, ZAYN | C87: SHELDON EARLY CHILDHOOD ACADEMY | D87: K | E87: RLA | F87: No | G87: No | I87: B | J87: N | K87: English | L87: GAINES, IDA | AM87: BOY | AN87: Above Benchmark | AO87: 418 | AP87: 0.69666667
A88: JACKSON, ALLISON | C88: SHELDON EARLY CHILDHOOD ACADEMY | D88: K | E88: RLA | F88: No | G88: No | I88: M | J88: Y | K88: English | L88: CATAPANO, APRIL | AM88: BOY | AN88: Well Below Benchmark | AO88: 270 | AP88: 0.45
A89: JAQUEZ, YARETZI | C89: SHELDON EARLY CHILDHOOD ACADEMY | D89: K | E89: RLA | F89: No | G89: No | I89: W | J89: N | K89: English | L89: WILLIAMS, JUNE | AM89: BOY | AN89: At Benchmark | AO89: 327 | AP89: 0.545
A90: JOHNSON, JEANA | C90: SHELDON EARLY CHILDHOOD ACADEMY | D90: K | E90: RLA | F90: No | G90: No | I90: W | J90: N | K90: English | L90: CASTILLO-LOPEZ, JOANA | AM90: BOY | AN90: Above Benchmark | AO90: 346 | AP90: 0.57666667
A91: JOHNSON, KAYSON | C91: SHELDON EARLY CHILDHOOD ACADEMY | D91: K | E91: RLA | F91: No | G91: No | I91: B | J91: N | K91: English | L91: HERRERA, STEPHANIE | AM91: BOY | AN91: Below Benchmark | AO91: 302 | AP91: 0.50333333
A92: JONES, DREAM | C92: SHELDON EARLY CHILDHOOD ACADEMY | D92: K | E92: RLA | F92: No | G92: No | I92: M | J92: Y | K92: English | L92: TOLLEY, ANALISA | AM92: BOY | AN92: At Benchmark | AO92: 308 | AP92: 0.51333333
A93: JUAREZ, MARLEEN | C93: SHELDON EARLY CHILDHOOD ACADEMY | D93: K | E93: RLA | F93: No | G93: No | I93: B | J93: N | K93: English | L93: NED-WILLIAMS, JASMINE | AM93: BOY | AN93: At Benchmark | AO93: 327 | AP93: 0.545
A94: KALIK, DAMIEN | C94: SHELDON EARLY CHILDHOOD ACADEMY | D94: K | E94: RLA | F94: No | G94: No | I94: M | J94: Y | K94: English | L94: LEZAMA, MARIA | AM94: BOY | AN94: Above Benchmark | AO94: 402 | AP94: 0.67
... A132: PARRISH, JAX | C132: SHELDON EARLY CHILDHOOD ACADEMY | D132: K | E132: RLA | F132: No | G132: No | I132: M | J132: Y | K132: English | L132: LUMPFORD, JOYLANN | AM132: BOY | AN132: Well Below Benchmark | AO132: 275 | AP132: 0.45833333
A133: PEARSON, DAVID | C133: SHELDON EARLY CHILDHOOD ACADEMY | D133: K | E133: RLA | F133: No | G133: No | I133: W | J133: N | K133: English | AM133: BOY | AN133: Well Below Benchmark | AO133: 247 | AP133: 0.41166667
A134: PEREZ, ISAAC | C134: SHELDON EARLY CHILDHOOD ACADEMY | D134: K | E134: RLA | F134: No | G134: No | I134: B | J134: N | K134: English | L134: TOLLEY, ANALISA | AM134: BOY | AN134: Well Below Benchmark | AO134: 272 | AP134: 0.45333333
A135: PEREZ, ULISES | C135: SHELDON EARLY CHILDHOOD ACADEMY | D135: K | E135: RLA | F135: No | G135: No | I135: M | J135: Y | K135: English | L135: MCDONALD, TAVIA | AM135: BOY | AN135: Below Benchmark | AO135: 303 | AP135: 0.505
A136: PEREZ CELIO, AARON | C136: SHELDON EARLY CHILDHOOD ACADEMY | D136: K | E136: RLA | F136: No | G136: No | I136: M | J136: Y | K136: English | L136: NED-WILLIAMS, JASMINE | AM136: BOY | AN136: Well Below Benchmark | AO136: 256 | AP136: 0.42666667
A137: PERKINS, JOURNEE | C137: SHELDON EARLY CHILDHOOD ACADEMY | D137: K | E137: RLA | F137: No | G137: No | I137: M | J137: Y | K137: English | L137: HERRERA, STEPHANIE | AM137: BOY | AN137: At Benchmark | AO137: 326 | AP137: 0.54333333
...

Sheet 2024-25 DIBELS BOY and EOY
A1: Student Name | B1: Local ID | C1: Current Campus | D1: Grade | E1: Subject | F1: Special Ed Indicator | G1: Economic Disadvantage | H1: Emergent Bilingual | I1: Ethnicity | K1: Test Lang | L1: Instructor | M1: Instructor ID | N1: 2024 STAAR | O1: STAAR Per Lev | P1: DCA#2 | Q1: DCA#2 Per Lev | R1: Delta | S1: Growth | T1: HB 1416 | U1: HB 1416 Delta | V1: Total Growth DCA#2 | W1: App | X1: Meets | Y1: Masters | Z1: CS | AA1: DCA 2 vs DCA 1 | AB1: DCA#1 | AC1: DCA#1 Per Lev | AD1: Delta | AE1: Growth | AF1: HB 1416 | AG1: HB 1616 Delta | AH1: Total Growth DCA 1 | AI1: App | AJ1: Meets | AK1: Masters | AL1: CS | AM1: Benchmark Period | AN1: Composite Level | AO1: Composite Score | AP1: % Comp
A2: ADELAJA, ANNA | C2: SHELDON EARLY CHILDHOOD ACADEMY | D2: K | E2: RLA | F2: No | G2: No | I2: Race | J2: Hispanic or Latino Ethnicity | K2: English | L2: LUMPFORD, JOYLANN | AM2: BOY | AN2: Below Benchmark | AO2: 281 | AP2: 0.46833333
A3: ADELAJA, ANNA | C3: SHELDON EARLY CHILDHOOD ACADEMY | D3: K | E3: RLA | F3: No | G3: No | I3: B | J3: N | K3: English | L3: LUMPFORD, JOYLANN | AM3: MOY | AN3: Well Below Benchmark | AO3: 330 | AP3: 0.55
A4: AGUILAR, AGUSTIN | C4: SHELDON EARLY CHILDHOOD ACADEMY | D4: K | E4: RLA | F4: No | G4: No | I4: B | J4: N | K4: English | L4: LEZAMA, MARIA | AM4: BOY | AN4: Below Benchmark | AO4: 294 | AP4: 0.49
A5: AGUILAR, AGUSTIN | C5: SHELDON EARLY CHILDHOOD ACADEMY | D5: K | E5: RLA | F5: No | G5: No | I5: M | J5: Y | K5: English | L5: LEZAMA, MARIA | AM5: MOY | AN5: At Benchmark | AO5: 375 | AP5: 0.625
A6: AGUILAR, ARIANA | C6: SHELDON EARLY CHILDHOOD ACADEMY | D6: K | E6: RLA | F6: No | G6: No | I6: M | J6: Y | K6: English | L6: MCDONALD, TAVIA | AM6: BOY | AN6: Above Benchmark | AO6: 390 | AP6: 0.65
A7: AGUILAR, ARIANA | C7: SHELDON EARLY CHILDHOOD ACADEMY | D7: K | E7: RLA | F7: No | G7: No | I7: M | J7: Y | K7: English | L7: MCDONALD, TAVIA | AM7: MOY | AN7: Above Benchmark | AO7: 399 | AP7: 0.665
A8: ALEXANDER, RANIYAH | C8: SHELDON EARLY CHILDHOOD ACADEMY | D8: K | E8: RLA | F8: No | G8: No | I8: M | J8: Y | K8: English | L8: MCDONALD, TAVIA | AM8: BOY | AN8: Above Benchmark | AO8: 333 | AP8: 0.555
A9: ALEXANDER, RANIYAH | C9: SHELDON EARLY CHILDHOOD ACADEMY | D9: K | E9: RLA | F9: No | G9: No | I9: B | J9: N | K9: English | L9: MCDONALD, TAVIA | AM9: MOY | AN9: Below Benchmark | AO9: 370 | AP9: 0.61666667
A10: ALEXANDER-YOUNG, PAISLEY | C10: SHELDON EARLY CHILDHOOD ACADEMY | D10: K | E10: RLA | F10: No | G10: No | I10: B | J10: N | K10: English | AM10: BOY | AN10: Below Benchmark | AO10: 297 | AP10: 0.495
A11: ALLEN, KAYCEN | C11: SHELDON EARLY CHILDHOOD ACADEMY | D11: K | E11: RLA | F11: No | G11: No | I11: B | J11: N | K11: English | L11: MCDONALD, TAVIA | AM11: BOY | AN11: Well Below Benchmark | AO11: 264 | AP11: 0.44
A12: ALLEN, KAYCEN | C12: SHELDON EARLY CHILDHOOD ACADEMY | D12: K | E12: RLA | F12: No | G12: No | I12: B | J12: N | K12: English | L12: MCDONALD, TAVIA | AM12: MOY | AN12: Well Below Benchmark | AO12: 320 | AP12: 0.53333333
A13: ALVARADO, JOSHUA | C13: SHELDON EARLY CHILDHOOD ACADEMY | D13: K | E13: RLA | F13: No | G13: No | I13: B | J13: N | K13: English | AM13: BOY | AN13: At Benchmark | AO13: 310 | AP13: 0.51666667
A14: ALVARADO, LUNA | C14: SHELDON EARLY CHILDHOOD ACADEMY | D14: K | E14: RLA | F14: No | G14: No | I14: M | J14: Y | K14: English | L14: GAINES, IDA | AM14: BOY | AN14: Well Below Benchmark | AO14: 269 | AP14: 0.44833333
A15: ALVARADO, LUNA | C15: SHELDON EARLY CHILDHOOD ACADEMY | D15: K | E15: RLA | F15: No | G15: No | I15: M | J15: Y | K15: English | L15: GAINES, IDA | AM15: MOY | AN15: Well Below Benchmark | AO15: 339 | AP15: 0.565
A16: ANCIRA, XANTINO | C16: SHELDON EARLY CHILDHOOD ACADEMY | D16: K | E16: RLA | F16: No | G16: No | I16: M | J16: Y | K16: English | L16: JENKINS, SARAH | AM16: BOY | AN16: At Benchmark | AO16: 306 | AP16: 0.51
A17: ANCIRA, XANTINO | C17: SHELDON EARLY CHILDHOOD ACADEMY | D17: K | E17: RLA | F17: No | G17: No | I17: M | J17: Y | K17: English | L17: JENKINS, SARAH | AM17: MOY | AN17: Below Benchmark | AO17: 364 | AP17: 0.60666667
A18: ANGULO, PRINCETON | C18: SHELDON EARLY CHILDHOOD ACADEMY | D18: K | E18: RLA | F18: No | G18: No | I18: M | J18: Y | K18: English | L18: JENKINS, SARAH | AM18: BOY | AN18: Below Benchmark | AO18: 289 | AP18: 0.48166667
A19: ARZU, JAHMIERE | C19: SHELDON EARLY CHILDHOOD ACADEMY | D19: K | E19: RLA | F19: No | G19: No | I19: M | J19: Y | K19: English | L19: NED-WILLIAMS, JASMINE | AM19: BOY | AN19: Below Benchmark | AO19: 280 | AP19: 0.46666667
A20: ARZU, JAHMIERE | C20: SHELDON EARLY CHILDHOOD ACADEMY | D20: K | E20: RLA | F20: No | G20: No | I20: B | J20: N | K20: English | L20: NED-WILLIAMS, JASMINE | AM20: MOY | AN20: Above Benchmark | AO20: 393 | AP20: 0.655
A21: ASCENCIO, FRANCISCO | C21: SHELDON EARLY CHILDHOOD ACADEMY | D21: K | E21: RLA | F21: No | G21: No | I21: B | J21: N | K21: English | L21: CASTILLO-LOPEZ, JOANA | AM21: BOY | AN21: Below Benchmark | AO21: 286 | AP21: 0.47666667
A22: ASCENCIO, FRANCISCO | C22: SHELDON EARLY CHILDHOOD ACADEMY | D22: K | E22: RLA | F22: No | G22: No | I22: M | J22: Y | K22: English | L22: CASTILLO-LOPEZ, JOANA | AM22: MOY | AN22: Below Benchmark | AO22: 364 | AP22: 0.60666667
A23: AVELLANEDA, DALYLAH | C23: SHELDON EARLY CHILDHOOD ACADEMY | D23: K | E23: RLA | F23: No | G23: No | I23: M | J23: Y | K23: English | L23: CATAPANO, APRIL | AM23: BOY | AN23: At Benchmark | AO23: 326 | AP23: 0.54333333
A24: AVELLANEDA, DALYLAH | C24: SHELDON EARLY CHILDHOOD ACADEMY | D24: K | E24: RLA | F24: No | G24: No | I24: M | J24: Y | K24: English | L24: CATAPANO, APRIL | AM24: MOY | AN24: At Benchmark | AO24: 382 | AP24: 0.63666667
A25: BAILEY, EZRA | C25: SHELDON EARLY CHILDHOOD ACADEMY | D25: K | E25: RLA | F25: No | G25: No | I25: M | J25: Y | K25: English | L25: CATAPANO, APRIL | AM25: BOY | AN25: Above Benchmark | AO25: 333 | AP25: 0.555
... A162: HILL, JEREMIAH | C162: SHELDON EARLY CHILDHOOD ACADEMY | D162: K | E162: RLA | F162: No | G162: No | I162: B | J162: N | K162: English | L162: ALLEN, NICKIE | AM162: BOY | AN162: Well Below Benchmark | AO162: 243 | AP162: 0.405
A163: HILL, QUEEN | C163: SHELDON EARLY CHILDHOOD ACADEMY | D163: K | E163: RLA | F163: No | G163: No | I163: M | J163: Y | K163: English | AM163: BOY | AN163: Well Below Benchmark | AO163: 254 | AP163: 0.42333333
A164: HINES, AMIER | C164: SHELDON EARLY CHILDHOOD ACADEMY | D164: K | E164: RLA | F164: No | G164: No | I164: M | J164: Y | K164: English | L164: NED-WILLIAMS, JASMINE | AM164: BOY | AN164: Above Benchmark | AO164: 387 | AP164: 0.645
A165: HINES, AMIER | C165: SHELDON EARLY CHILDHOOD ACADEMY | D165: K | E165: RLA | F165: No | G165: No | I165: B | J165: N | K165: English | L165: NED-WILLIAMS, JASMINE | AM165: MOY | AN165: Above Benchmark | AO165: 418 | AP165: 0.69666667
A166: HUBBARD, SEBASTIAN | C166: SHELDON EARLY CHILDHOOD ACADEMY | D166: K | E166: RLA | F166: No | G166: No | I166: B | J166: N | K166: English | L166: JENKINS, SARAH | AM166: BOY | AN166: Above Benchmark | AO166: 339 | AP166: 0.565
A167: HUBBARD, SEBASTIAN | C167: SHELDON EARLY CHILDHOOD ACADEMY | D167: K | E167: RLA | F167: No | G167: No | I167: B | J167: N | K167: English | L167: JENKINS, SARAH | AM167: MOY | AN167: Above Benchmark | AO167: 393 | AP167: 0.655
A168: HYACINTH, DARIUS | C168: SHELDON EARLY CHILDHOOD ACADEMY | D168: K | E168: RLA | F168: No | G168: No | I168: B | J168: N | K168: English | L168: GAINES, IDA | AM168: BOY | AN168: At Benchmark | AO168: 313 | AP168: 0.52166667
A169: HYACINTH, DARIUS | C169: SHELDON EARLY CHILDHOOD ACADEMY | D169: K | E169: RLA | F169: No | G169: No | I169: B | J169: N | K169: English | L169: GAINES, IDA | AM169: MOY | AN169: At Benchmark | AO169: 388 | AP169: 0.64666667
A170: HYACINTH, NYA | C170: SHELDON EARLY CHILDHOOD ACADEMY | D170: K | E170: RLA | F170: No | G170: No | I170: B | J170: N | K170: English | L170: LEZAMA, MARIA | AM170: BOY | AN170: Well Below Benchmark | AO170: 262 | AP170: 0.43666667
A171: HYACINTH, NYA | C171: SHELDON EARLY CHILDHOOD ACADEMY | D171: K | E171: RLA | F171: No | G171: No | I171: B | J171: N | K171: English | L171: LEZAMA, MARIA | AM171: MOY | AN171: Well Below Benchmark | AO171: 353 | AP171: 0.58833333
A172: IVY, ZAYN | C172: SHELDON EARLY CHILDHOOD ACADEMY | D172: K | E172: RLA | F172: No | G172: No | I172: B | J172: N | K172: English | L172: GAINES, IDA | AM172: BOY | AN172: Above Benchmark | AO172: 418 | AP172: 0.69666667
A173: IVY, ZAYN | C173: SHELDON EARLY CHILDHOOD ACADEMY | D173: K | E173: RLA | F173: No | G173: No | I173: M | J173: Y | K173: English | L173: GAINES, IDA | AM173: MOY | AN173: Above Benchmark | AO173: 466 | AP173: 0.77666667
A174: JACKSON, ALLISON | C174: SHELDON EARLY CHILDHOOD ACADEMY | D174: K | E174: RLA | F174: No | G174: No | I174: M | J174: Y | K174: English | L174: CATAPANO, APRIL | AM174: BOY | AN174: Well Below Benchmark | AO174: 270 | AP174: 0.45
A175: JACKSON, ALLISON | C175: SHELDON EARLY CHILDHOOD ACADEMY | D175: K | E175: RLA | F175: No | G175: No | I175: W | J175: N | K175: English | L175: CATAPANO, APRIL | AM175: MOY | AN175: Well Below Benchmark | AO175: 340 | AP175: 0.56666667
... A263: PARRISH, JAX | C263: SHELDON EARLY CHILDHOOD ACADEMY | D263: K | E263: RLA | F263: No | G263: No | I263: W | J263: N | K263: English | L263: LUMPFORD, JOYLANN | AM263: MOY | AN263: Below Benchmark | AO263: 361 | AP263: 0.60166667
...
